<mujoco model="wire_insertion">
    <custom>
<!--        <numeric data="0.0   0.21 0.01497 0.5 -0.5 -0.5 0.5" name="0_part0_initpos" />-->
<!--        <numeric data="-0.37 0.31 0.01497 0.499854 0.499854 -0.500146 -0.500146" name="1_part1_initpos" />-->
<!--        <numeric data="-0.37 0.21 0.01497 0.500129 0.500129 0.499871 0.499871" name="2_part2_initpos" />-->
<!--        <numeric data="0.0   0.31 0.01497 0.5 -0.5 0.5 -0.5" name="3_part3_initpos" />-->
        <numeric data="0.4 0.25 0.051527 1 0 0 0" name="wire1_initpos" />
<!--        <numeric data="0.3 0.45 0.051527 1 0 0 0" name="wire1_initpos" />-->
<!--        <numeric data="0.6 0.27 0.051527 0 0 0 1" name="wire2_initpos" />-->
<!--        <numeric data="0.0 0.2 0.07 0.7073883 0 0.7068252 0" name="insertion_hole_1_initpos" />-->
        <!-- horizontal-->
        <numeric data="0.2 0.25 0.029527 1 0 0 0" name="table1_initpos" />
        <!-- vertical-->
<!--        <numeric data="-0.1 0.0 0.052527 0.7073883 -0.7068252 0 0" name="table1_initpos" />&ndash;&gt;-->
    </custom>
    <asset>
        <material name="table_mat" specular="0" shininess="0.5" reflectance="0" rgba="0.93 0.93 0.93 1"/>
        <!-- ceramic table texture and material-->
        <texture file="../textures/ceramic.png" type="cube" name="tex-ceramic"/>
        <material name="table_ceramic" reflectance="0.0" shininess="0.0" specular="0.2" texrepeat="1 1" texture="tex-ceramic" />
        <texture file="../textures/steel-scratched.png" type="cube" name="steel-metal"/>
        <material name="smetal" reflectance="1.0" shininess="1.0" specular="1.0" texrepeat="1 1" texture="steel-metal" texuniform="true"/>
        <texture file="../textures/brass-ambra.png" type="cube" name="brass-metal"/>
        <material name="bmetal"  reflectance="1.0" shininess="1.0" specular="1.0" texrepeat="1 1" texture="brass-metal" texuniform="true"/>
        <mesh file="table_lack_0825/table.stl" name="part4" scale="0.015 0.015 0.02" />
        <texture file="../textures/light-wood.png" name="tex-light-wood" type="2d" />
        <material name="pencil-wood" reflectance="0.5" texrepeat="20 20" texture="tex-light-wood" texuniform="true" />
        <texture file="../textures/red-wood.png" name="tex-red-wood" type="2d" />
        <material name="red-wood" reflectance="0.5" texrepeat="20 20" texture="tex-red-wood" texuniform="true" />
    </asset>

    <equality>
<!--        <weld active="false" body1="wire1" body2="insertion_hole_1" solimp="1 1 0.5" solref="0.01 0.3" />-->
        <weld active="false" body1="wire1" body2="table1" solimp="1 1 0.5" solref="0.01 0.3" />
<!--        <weld active="true" body1="shelf" solimp="1 1 0.5" solref="0.01 0.3" />-->
    </equality>

    <compiler meshdir=""/>
    <size njmax="8000" nconmax="4000"/>

    <worldbody>
        <!--Wire-->
<!--        <body name="wire1" pos="-0.2 0.2 0.351527" quat="0.7073883 0 -0.7068252 0">-->
<!--        <body name="wire1" pos="0.1 -0.04005574 -0.06998405" quat="0.7073883 0 0 -0.7068252">-->
        <body name="wire1" pos="0.16 0.185 0.122" quat="1 0 0 0">-->
<!--            <freejoint/>-->
<!--            <include file="./rope_expanded_short.xml"/>-->
<!--            <body xmlns:xi="http://www.w3.org/2001/XInclude">-->
<!--            <xi:include href="source.xml" parse="xml" />-->
<!--            </body>-->
            <inertial pos="0.055 0 0" quat="0.707107 0 0.707107 0" mass="0.00274889" diaginertia="2.97797e-07 2.97797e-07 3.43612e-08" />
            <geom name="wire1_I1_geom" conaffinity="0" contype="0" pos="0 0 0" size="0.005 0.01" quat="0.707107 0 0.707107 0" rgba="0.1 0.7 0.7 1" group="1" solref="0.001 1" type="capsule" />-->
            <geom name="noviz_collision_wire1_I1"  size="0.005 0.01" quat="0.707107 0 0.707107 0" type="capsule" rgba="0 0 0 0" group="0" solref="0.001 1"/>
            <geom name="wire1_G0_geom" condim="3" conaffinity="0" contype="0" pos="0.065 0 0" size="0.01 0.05" quat="0.707107 0 0.707107 0" rgba="0.1 0.1 0.1 1" group="1" solref="0.001 1" type="capsule" />-->
            <geom name="noviz_collision_wire1_G0" pos="0.065 0 0" size="0.01 0.05" quat="0.707107 0 0.707107 0" type="capsule" rgba="0 0 0 0" group="0" solref="0.001 1"/>
<!--            <geom name="G0" pos="0.045 0 0" size="0.005 0.03" quat="0.707107 0 0.707107 0" type="capsule" rgba="0.1 0.1 0.1 1" group="0" />-->
            <!--site for gripper-->
            <site group="1" name="wire1_ltgt_site0" pos="0.075 0.01 0" rgba="0.9019 0.0980 0.2941 0.3" size="0.005 0.005 0.005" type="sphere" />
            <site group="1" name="wire1_rtgt_site0" pos="0.075 -0.01 0" rgba="0.9019 0.0980 0.2941 0.3" size="0.005 0.005 0.005" type="sphere" />
            <!--site for hole-->
            <site group="0" name="wire-hole,conn_site1" pos="-0.0125 0.0 0.0" quat="0.707107 0 0.707107 0" rgba="0.9019 0.0980 0.2941 0.3" size="0.005" />
            <!-- <site name="wire1_horizontal_radius_site" pos="0.0 0.0 0.0" rgba="1 1 0 1" size="0.0035" />-->
            <!--site for connection-->
            <site group="1" name="wire1_end" pos="0.125 0 0" quat="0.707107 0 -0.707107 0" rgba="0.9019 0.0980 0.2941 0.3" size="0.005 0.005 0.005" type="sphere" />
            <site name="wire1_horizontal_radius_site" pos="0.065 0 0" rgba="1 1 0 1" size="0.0055" />
            <body name="composite_B1" pos="0.14 0 0">
<!--                <inertial pos="0 0 0" quat="0.707107 0 0.707107 0" mass="0.00274889" diaginertia="2.97797e-07 2.97797e-07 3.43612e-08" />-->
<!--                        <joint name="J0_1" pos="-0.0175 0 0" axis="0 1 0" group="3" damping="0.005" />-->
<!--                        <joint name="J1_1" pos="-0.0175 0 0" axis="0 0 1" group="3" damping="0.005" />-->
<!--                        <geom name="G1" size="0.005 0.015" quat="0.707107 0 0.707107 0" type="capsule" rgba="0.1 0.1 0.1 1" group="0"/>-->
<!--                        <site name="B1_horizontal_radius_site" pos="0 0 0" rgba="1 1 0 1" size="0.0055" />-->
                <inertial pos="0 0 0" quat="0.707107 0 0.707107 0" mass="0.00001" diaginertia="2.97797e-07 2.97797e-07 3.43612e-08" />
                <joint name="J0_1" pos="-0.0175 0 0" group="3" damping="0.003" type="ball"/>
<!--                <joint name="J0_1" pos="-0.0175 0 0" axis="0 1 0" group="3" damping="0.003"/>-->
<!--                <joint name="J1_1" pos="-0.0175 0 0" axis="0 0 1" group="3" damping="0.003"/>-->
<!--                <joint name="J2_1" pos="-0.0175 0 0" axis="1 0 0" group="3" damping="0.003"/>-->
                <site group="1" name="B1_ltgt_site0" pos="0.0075 0.01 0" rgba="0 0 0 0" size="0.005 0.005 0.005" type="sphere" />
                <site group="1" name="B1_rtgt_site0" pos="0.0075 -0.01 0" rgba="0 0 0 0" size="0.005 0.005 0.005" type="sphere" />
                <geom name="B1_G1_geom" conaffinity="0" contype="0" pos="0 0 0" size="0.01 0.015" quat="0.707107 0 0.707107 0" rgba="0.7 0.7 0.7 1" group="1" solref="0.001 1" type="capsule" />-->
                <geom name="noviz_collision_B1_G1" pos="0 0 0" size="0.01 0.015" quat="0.707107 0 0.707107 0" type="capsule" rgba="0 0 0 0" group="0" solref="0.001 1"/>
<!--                <geom name="G1" size="0.01 0.015" quat="0.707107 0 0.707107 0" typ e="capsule" rgba="0.1 0.1 0.1 1" group="0"/>-->
<!--                <site name="B1_horizontal_radius_site" pos="0 0 0" rgba="1 1 0 1" size="0.0055" />-->
                <body name="composite_B2" pos="0.035 0 0">
                    <inertial pos="0 0 0" quat="0.707107 0 0.707107 0" mass="0.00001" diaginertia="2.97797e-07 2.97797e-07 3.43612e-08" />
                    <joint name="J0_2" pos="-0.0175 0 0" group="3" damping="0.003" type="ball"/>
<!--                    <joint name="J0_2" pos="-0.0175 0 0" axis="0 1 0" group="3" damping="0.003" />-->
<!--                    <joint name="J1_2" pos="-0.0175 0 0" axis="0 0 1" group="3" damping="0.003" />-->
                    <geom name="B2_G1_geom" conaffinity="0" contype="0" pos="0 0 0" size="0.01 0.015" quat="0.707107 0 0.707107 0" rgba="0.7 0.7 0.7 1" group="1" solref="0.001 1" type="capsule" />-->
                    <geom name="noviz_collision_B2_G1" pos="0 0 0" size="0.01 0.015" quat="0.707107 0 0.707107 0" type="capsule" rgba="0 0 0 0" group="0" solref="0.001 1"/>
                    <body name="composite_B3" pos="0.035 0 0">
                        <inertial pos="0 0 0" quat="0.707107 0 0.707107 0" mass="0.00001" diaginertia="2.97797e-07 2.97797e-07 3.43612e-08" />
                        <joint name="J0_3" pos="-0.0175 0 0" group="3" damping="0.003" type="ball"/>
<!--                        <joint name="J0_3" pos="-0.0175 0 0" axis="0 1 0" group="3" damping="0.003" />-->
<!--                        <joint name="J1_3" pos="-0.0175 0 0" axis="0 0 1" group="3" damping="0.003" />-->
                        <geom name="B3_G1_geom" conaffinity="0" contype="0" pos="0 0 0" size="0.01 0.015" quat="0.707107 0 0.707107 0" rgba="0.7 0.7 0.7 1" group="1" solref="0.001 1" type="capsule" />-->
                        <geom name="noviz_collision_B3_G1" pos="0 0 0" size="0.01 0.015" quat="0.707107 0 0.707107 0" type="capsule" rgba="0 0 0 0" group="0" solref="0.001 1"/>
                        <body name="composite_B4" pos="0.035 0 0">
                            <inertial pos="0 0 0" quat="0.707107 0 0.707107 0" mass="0.00001" diaginertia="2.97797e-07 2.97797e-07 3.43612e-08" />
                            <joint name="J0_4" pos="-0.0175 0 0" group="3" damping="0.003" type="ball"/>
<!--                            <joint name="J0_4" pos="-0.0175 0 0" axis="0 1 0" group="3" damping="0.003" />-->
<!--                            <joint name="J1_4" pos="-0.0175 0 0" axis="0 0 1" group="3" damping="0.003" />-->
                            <geom name="B4_G1_geom" conaffinity="0" contype="0" pos="0 0 0" size="0.01 0.015" quat="0.707107 0 0.707107 0" rgba="0.7 0.7 0.7 1" group="1" solref="0.001 1" type="capsule" />-->
                            <geom name="noviz_collision_B4_G1" pos="0 0 0" size="0.01 0.015" quat="0.707107 0 0.707107 0" type="capsule" rgba="0 0 0 0" group="0" solref="0.001 1"/>
                            <body name="composite_B5" pos="0.035 0 0">
                                <inertial pos="0 0 0" quat="0.707107 0 0.707107 0" mass="0.00001" diaginertia="2.97797e-07 2.97797e-07 3.43612e-08" />
                                <joint name="J0_5" pos="-0.0175 0 0" group="3" damping="0.003" type="ball"/>
<!--                                <joint name="J0_5" pos="-0.0175 0 0" axis="0 1 0" group="3" damping="0.003" />-->
<!--                                <joint name="J1_5" pos="-0.0175 0 0" axis="0 0 1" group="3" damping="0.003" />-->
                                <geom name="B5_G1_geom" conaffinity="0" contype="0" pos="0 0 0" size="0.01 0.015" quat="0.707107 0 0.707107 0" rgba="0.7 0.7 0.7 1" group="1" solref="0.001 1" type="capsule" />-->
                                <geom name="noviz_collision_B5_G1" pos="0 0 0" size="0.01 0.015" quat="0.707107 0 0.707107 0" type="capsule" rgba="0 0 0 0" group="0" solref="0.001 1"/>
                                <body name="composite_B6" pos="0.035 0 0">
                                    <inertial pos="0 0 0" quat="0.707107 0 0.707107 0" mass="0.00001" diaginertia="2.97797e-07 2.97797e-07 3.43612e-08" />
                                    <joint name="J0_6" pos="-0.0175 0 0" group="3" damping="0.003" type="ball"/>
<!--                                    <joint name="J0_6" pos="-0.0175 0 0" axis="0 1 0" group="3" damping="0.003" />-->
<!--                                    <joint name="J1_6" pos="-0.0175 0 0" axis="0 0 1" group="3" damping="0.003" />-->
                                    <geom name="B6_G1_geom" conaffinity="0" contype="0" pos="0 0 0" size="0.01 0.015" quat="0.707107 0 0.707107 0" rgba="0.7 0.7 0.7 1" group="1" solref="0.001 1" type="capsule" />-->
                                    <geom name="noviz_collision_B6_G1" pos="0 0 0" size="0.01 0.015" quat="0.707107 0 0.707107 0" type="capsule" rgba="0 0 0 0" group="0" solref="0.001 1"/>
                                    <body name="composite_B7" pos="0.035 0 0">
                                        <inertial pos="0 0 0" quat="0.707107 0 0.707107 0" mass="0.00001" diaginertia="2.97797e-07 2.97797e-07 3.43612e-08" />
                                        <joint name="J0_7" pos="-0.0175 0 0" group="3" damping="0.003" type="ball"/>
<!--                                        <joint name="J0_7" pos="-0.0175 0 0" axis="0 1 0" group="3" damping="0.003" />-->
<!--                                        <joint name="J1_7" pos="-0.0175 0 0" axis="0 0 1" group="3" damping="0.003" />-->
                                        <geom name="B7_G1_geom" conaffinity="0" contype="0" pos="0 0 0" size="0.01 0.015" quat="0.707107 0 0.707107 0" rgba="0.7 0.7 0.7 1" group="1" solref="0.001 1" type="capsule" />-->
                                        <geom name="noviz_collision_B7_G1" pos="0 0 0" size="0.01 0.015" quat="0.707107 0 0.707107 0" type="capsule" rgba="0 0 0 0" group="0" solref="0.001 1"/>
                                        <body name="composite_B8" pos="0.035 0 0">
                                            <inertial pos="0 0 0" quat="0.707107 0 0.707107 0" mass="0.00001" diaginertia="2.97797e-07 2.97797e-07 3.43612e-08" />
                                            <joint name="J0_8" pos="-0.0175 0 0" group="3" damping="0.003" type="ball"/>
<!--                                            <joint name="J0_8" pos="-0.0175 0 0" axis="0 1 0" group="3" damping="0.003" />-->
<!--                                            <joint name="J1_8" pos="-0.0175 0 0" axis="0 0 1" group="3" damping="0.003" />-->
                                            <geom name="B8_G1_geom" conaffinity="0" contype="0" pos="0 0 0" size="0.01 0.015" quat="0.707107 0 0.707107 0" rgba="0.7 0.7 0.7 1" group="1" solref="0.001 1" type="capsule" />-->
                                            <geom name="noviz_collision_B8_G1" pos="0 0 0" size="0.01 0.015" quat="0.707107 0 0.707107 0" type="capsule" rgba="0 0 0 0" group="0" solref="0.001 1"/>
                                            <body name="composite_B9" pos="0.035 0 0">
                                                <inertial pos="0 0 0" quat="0.707107 0 0.707107 0" mass="0.00001" diaginertia="2.97797e-07 2.97797e-07 3.43612e-08" />
                                                <joint name="J0_9" pos="-0.0175 0 0" group="3" damping="0.003" type="ball"/>
<!--                                                <joint name="J0_9" pos="-0.0175 0 0" axis="0 1 0" group="3" damping="0.003" />-->
<!--                                                <joint name="J1_9" pos="-0.0175 0 0" axis="0 0 1" group="3" damping="0.003" />-->
                                                <geom name="B9_G1_geom" conaffinity="0" contype="0" pos="0 0 0" size="0.01 0.015" quat="0.707107 0 0.707107 0" rgba="0.7 0.7 0.7 1" group="1" solref="0.001 1" type="capsule" />-->
                                                <geom name="noviz_collision_B9_G1" pos="0 0 0" size="0.01 0.015" quat="0.707107 0 0.707107 0" type="capsule" rgba="0 0 0 0" group="0" solref="0.001 1"/>
                                                <body name="composite_B10" pos="0.035 0 0">
                                                    <inertial pos="0 0 0" quat="0.707107 0 0.707107 0" mass="0.00001" diaginertia="2.97797e-07 2.97797e-07 3.43612e-08" />
                                                    <joint name="J0_10" pos="-0.0175 0 0" group="3" damping="0.003" type="ball"/>
<!--                                                    <joint name="J0_10" pos="-0.0175 0 0" axis="0 1 0" group="3" damping="0.003" />-->
<!--                                                    <joint name="J1_10" pos="-0.0175 0 0" axis="0 0 1" group="3" damping="0.003" />-->
                                                    <geom name="B10_G1_geom" conaffinity="0" contype="0" pos="0 0 0" size="0.01 0.015" quat="0.707107 0 0.707107 0" rgba="0.7 0.7 0.7 1" group="1" solref="0.001 1" type="capsule" />-->
                                                    <geom name="noviz_collision_B10_G1" pos="0 0 0" size="0.01 0.015" quat="0.707107 0 0.707107 0" type="capsule" rgba="0 0 0 0" group="0" solref="0.001 1"/>
                                                    <body name="composite_B11" pos="0.035 0 0">
                                                        <inertial pos="0 0 0" quat="0.707107 0 0.707107 0" mass="0.00001" diaginertia="2.97797e-07 2.97797e-07 3.43612e-08" />
                                                        <joint name="J0_11" pos="-0.0175 0 0" group="3" damping="0.003" type="ball"/>
                                                        <geom name="B11_G1_geom" conaffinity="0" contype="0" pos="0 0 0" size="0.01 0.015" quat="0.707107 0 0.707107 0" rgba="0.7 0.7 0.7 1" group="1" solref="0.001 1" type="capsule" />-->
                                                        <geom name="noviz_collision_B11_G1" pos="0 0 0" size="0.01 0.015" quat="0.707107 0 0.707107 0" type="capsule" rgba="0 0 0 0" group="0" solref="0.001 1"/>
                                                        <body name="composite_B12" pos="0.035 0 0">
                                                            <inertial pos="0 0 0" quat="0.707107 0 0.707107 0" mass="0.00001" diaginertia="2.97797e-07 2.97797e-07 3.43612e-08" />
                                                            <joint name="J0_12" pos="-0.0175 0 0" group="3" damping="0.003" type="ball"/>
                                                            <geom name="B12_G1_geom" conaffinity="0" contype="0" pos="0 0 0" size="0.01 0.015" quat="0.707107 0 0.707107 0" rgba="0.7 0.7 0.7 1" group="1" solref="0.001 1" type="capsule" />-->
                                                            <geom name="noviz_collision_B12_G1" pos="0 0 0" size="0.01 0.015" quat="0.707107 0 0.707107 0" type="capsule" rgba="0 0 0 0" group="0" solref="0.001 1"/>
                                                            <body name="composite_wire2" pos="0.015 0 0">
                                                                <inertial pos="0.055 0 0" quat="0.707107 0 0.707107 0" mass="0.000274889" diaginertia="2.97797e-07 2.97797e-07 3.43612e-08" />
                                                                <joint name="J0_wire2" pos="-0.0175 0 0" group="3" damping="0.003" type="ball"/>
        <!--                                                        <joint name="J0_11" pos="0 0 0" axis="0 1 0" group="3" damping="0.005" />-->
        <!--                                                        <joint name="J1_11" pos="0 0 0" axis="0 0 1" group="3" damping="0.005" />-->
                                                                <geom name="wire2_G0_geom" conaffinity="0" contype="0" pos="0.055 0 0" size="0.01 0.05" quat="0.707107 0 0.707107 0" rgba="0.1 0.1 0.1 1" group="1" solref="0.001 1" type="capsule" />-->
                                                                <geom name="noviz_collision_wire2_G0" pos="0.055 0 0" size="0.01 0.05" quat="0.707107 0 0.707107 0" type="capsule" rgba="0 0 0 0" group="0" solref="0.001 1"/>
                                                                <geom name="wire2_I2_geom" conaffinity="0" contype="0" pos="0.115 0 0" size="0.005 0.01" quat="0.707107 0 0.707107 0" rgba="0.1 0.7 0.7 1" group="1" solref="0.001 1" type="capsule" />-->
                                                                <geom name="noviz_collision_wire2_I2" pos="0.115 0 0" size="0.005 0.01" quat="0.707107 0 0.707107 0" type="capsule" rgba="0 0 0 0" group="0" solref="0.001 1"/>
        <!--                                                        <geom name="wire2_G0" pos="0.045 0 0" size="0.005 0.03" quat="0.707107 0 0.707107 0" type="capsule" rgba="0.1 0.1 0.1 1" group="0" />-->
                                                                <!--site for gripper-->
                                                                <site group="1" name="wire2_ltgt_site0" pos="0.055 0.01 0" rgba="0.9019 0.0980 0.2941 0.3" size="0.005 0.005 0.005" type="sphere" />
                                                                <site group="1" name="wire2_rtgt_site0" pos="0.055 -0.01 0" rgba="0.9019 0.0980 0.2941 0.3" size="0.005 0.005 0.005" type="sphere" />
                                                                <!--site for hole-->
        <!--                                                        <site group="0" name="wire2-hole,0,90,180,270,conn_site2" pos="0.125 0.0 0.0" quat="0.707107 0 0.707107 0" rgba="0 0 0 0" size="0.005" />-->
                                                                <!--site for connection-->
                                                                <site group="1" name="wire2_end" pos="-0.005 0.0 0.0" quat="0 0 1 0" rgba="0 0 0 0" size="0.005 0.005 0.005" type="sphere" />
                                                                <site name="wire2_horizontal_radius_site" pos="0.055 0 0" rgba="0 0 0 0" size="0.0055" />
        <!--                                                                    <joint type="free"/>-->
                                                            </body>
                                                        </body>
                                                    </body>
                                                </body>
                                            </body>
                                        </body>
                                    </body>
                                </body>
                            </body>
                        </body>
                    </body>
                </body>
            </body>
        </body>

<!--        <body name="wire2" pos="0.2 0.2 0.051527" quat="0 0 0 1">-->
<!--            <inertial pos="0.055 0 0" quat="0.707107 0 0.707107 0" mass="0.000274889" diaginertia="2.97797e-07 2.97797e-07 3.43612e-08" />-->
<!--            <geom name="wire2_I2_geom" conaffinity="0" contype="0" pos="0 0 0" size="0.005 0.01" quat="0.707107 0 0.707107 0" rgba="0.1 0.7 0.7 1" solref="0.001 1" type="capsule" />&ndash;&gt;-->
<!--            <geom name="noviz_collision_wire2_I2"  size="0.005 0.01" quat="0.707107 0 0.707107 0" type="capsule" rgba="0 0 0 0" group="0" solref="0.001 1"/>-->
<!--            <geom name="wire2_G0_geom" conaffinity="0" contype="0" pos="0.065 0 0" size="0.01 0.05" quat="0.707107 0 0.707107 0" rgba="0.1 0.1 0.1 1" solref="0.001 1" type="capsule" />&ndash;&gt;-->
<!--            <geom name="noviz_collision_wire2_G0" pos="0.065 0 0" size="0.01 0.05" quat="0.707107 0 0.707107 0" type="capsule" rgba="0 0 0 0" group="0" solref="0.001 1"/>-->
<!--            <geom name="wire2_G0" pos="0.045 0 0" size="0.005 0.03" quat="0.707107 0 0.707107 0" type="capsule" rgba="0.1 0.1 0.1 1" group="0" />-->
<!--            &lt;!&ndash;site for gripper&ndash;&gt;-->
<!--            <site group="1" name="wire2_ltgt_site0" pos="0.075 0.01 0" rgba="0.9019 0.0980 0.2941 0.3" size="0.005 0.005 0.005" type="sphere" />-->
<!--            <site group="1" name="wire2_rtgt_site0" pos="0.075 -0.01 0" rgba="0.9019 0.0980 0.2941 0.3" size="0.005 0.005 0.005" type="sphere" />-->
<!--            &lt;!&ndash;site for hole&ndash;&gt;-->
<!--&lt;!&ndash;            <site group="0" name="wire-hole,0,90,180,270,conn_site1" pos="-0.0125 0.0 0.0" quat="0.707107 0 0.707107 0" rgba="0 0 0 0" size="0.005" />&ndash;&gt;-->
<!--            &lt;!&ndash;site for connection&ndash;&gt;-->
<!--            <site group="1" name="wire2_end" pos="0.125 0 0" quat="0.707107 0 0.707107 0" rgba="0.9019 0.0980 0.2941 0.3" size="0.005 0.005 0.005" type="sphere" />-->
<!--            <site name="wire2_horizontal_radius_site" pos="0.065 0 0" rgba="0 0 0 0" size="0.0055" />-->
<!--&lt;!&ndash;            <joint type="free"/>&ndash;&gt;-->
<!--        </body>-->

        <!-- Table -->
        <body name="table1" pos="0.2 0.25 0.029527" quat="1 0 0 0">
<!--        <body name="table1" pos="0.0 0.0 0.0" quat="0.7073883 0.7068252 0 0">-->
            <geom conaffinity="0" contype="0" density="0" material="pencil-wood" mesh="part4" name="table1_geom" pos="0 0 0" rgba="0.82 0.71 0.55 1" group="1" solref="0.001 1" type="mesh" />
            <geom density="50" name="noviz_collision_table1_0" pos="0 0 0" quat="1 0 0 0" rgba="0 0 0 0" group="0" size="0.32 0.12 0.02" solref="0.001 1" type="box" />
            <site name="table1_corner_site1" pos="-0.385 -0.140 -0.023" rgba="0 0 0 0" size="0.005" />
            <site name="table1_corner_site2" pos="-0.385 0.140 -0.023" rgba="0 0 0 0" size="0.005" />
            <site name="table1_corner_site3" pos="0.385 -0.140 -0.023" rgba="0 0 0 0" size="0.005" />
            <site name="table1_corner_site4" pos="0.385 0.140 -0.023" rgba="0 0 0 0" size="0.005" />
            <site name="table1_corner_site5" pos="-0.385 -0.140 0.0233" rgba="0 0 0 0" size="0.005" />
            <site name="table1_corner_site6" pos="-0.385 0.140 0.0233" rgba="0 0 0 0" size="0.005" />
            <site name="table1_corner_site7" pos="0.385 -0.140 0.0233" rgba="0 0 0 0" size="0.005" />
            <site name="table1_corner_site8" pos="0.385 0.140 0.0233" rgba="0 0 0 0" size="0.005" />
            <site name="table1_bottom_site" pos="0.0 0.0 -0.0" rgba="0 0 0 0" size="0.0066" />
            <site name="table1_top_site" pos="0.0 0.0 0.02" rgba="0 0 0 0" size="0.0066" />
<!--            <site group="0" name="hole-wire,0,90,180,270,conn_site1" pos="0.1 -0.07 0.02" rgba="0.9019 0.0980 0.2941 0.3" size="0.005" />-->
            <site name="table1_horizontal_radius_site" pos="0.0 0.0 0.0" rgba="0 0 0 0" size="0.18" />
<!--            &lt;!&ndash;Hole Base&ndash;&gt;-->
<!--            <geom conaffinity="0" contype="0" density="0" material="pencil-wood" size="0.03 0.00825 0.01" name="base1_geom" group="1" pos="0.0 -0.07 0.05" quat="0.7073883 0 0.7068252 0" solref="0.001 1" type="box" />-->
<!--            <geom density="100" name="noviz_collision_base1" group="0" pos="0.0 -0.07 0.05" quat="0.7073883 0 0.7068252 0" rgba="0 0 0 0" size="0.03 0.00825 0.01" friction="0.95 0.3 0.2" solref="0.001 1" type="box" />-->

            <!--Hole 1-->
            <body name="composite_hole1" pos="-0.1 0 0.08825" quat="0.7071408 0 0.7070727 0">
                <!-- Base-->
                <geom conaffinity="0" contype="0" density="0" material="pencil-wood" size="0.03 0.00825 0.01" name="base1_geom" group="1" pos="0.03825 -0.07 0" quat="1 0 0 0" solref="0.001 1" type="box" />
                <geom density="100" name="noviz_collision_base1" group="0" pos="0.03825 -0.07 0" quat="1 0 0 0" rgba="0 0 0 0" size="0.03 0.00825 0.01" friction="0.95 0.3 0.2" solref="0.001 1" type="box" />
                <!-- Hole-->
                <geom conaffinity="0" contype="0" density="0" material="smetal" size="0.01 0.0016  0.00825" name="hole1_1_geom" group="1" pos="0.0 -0.07665  0" quat="0.7073883 0 0.7068252 0" solref="0.001 1" type="box" />
                <geom density="100" name="noviz_collision_hole1_1" group="0" pos="0.0 -0.07665  0" quat="0.7073883 0 0.7068252 0" rgba="0 0 0 0" size="0.01 0.0016  0.00825" friction="0.95 0.3 0.2" solref="0.001 1" type="box" />
                <geom conaffinity="0" contype="0" density="0" material="smetal" size="0.01 0.00625 0.0016" name="hole1_2_geom" group="1" pos="-0.00665 -0.07 0" quat="0.7073883 0 0.7068252 0" solref="0.001 1" type="box" />
                <geom density="100" name="noviz_collision_hole1_2" group="0" pos="-0.00665 -0.07 0" quat="0.7073883 0 0.7068252 0" rgba="0 0 0 0" size="0.01 0.00625 0.0016" friction="0.95 0.3 0.2" solref="0.001 1" type="box" />
                <geom conaffinity="0" contype="0" density="0" material="smetal" size="0.01 0.00625 0.0016" name="hole1_3_geom" group="1" pos="0.00665 -0.07 0" quat="0.7073883 0 0.7068252 0" solref="0.001 1" type="box" />
                <geom density="100" name="noviz_collision_hole1_3" group="0" pos="0.00665 -0.07 0" quat="0.7073883 0 0.7068252 0" rgba="0 0 0 0" size="0.01 0.00625 0.0016" friction="0.95 0.3 0.2" solref="0.001 1" type="box" />
                <geom conaffinity="0" contype="0" density="0" material="smetal" size="0.01 0.0016 0.00825" name="hole1_4_geom" group="1" pos="0.0 -0.06335 0" quat="0.7073883 0 0.7068252 0" solref="0.001 1" type="box" />
                <geom density="100" name="noviz_collision_hole1_4" group="0" pos="0.0 -0.06335 0" quat="0.7073883 0 0.7068252 0" rgba="0 0 0 0" size="0.01 0.0016 0.00825" friction="0.95 0.3 0.2" solref="0.001 1" type="box" />
                <geom conaffinity="0" contype="0" density="0" material="smetal" size="0.0021 0.00825 0.00825" name="hole1_5_geom" group="1" pos="0.0 -0.07 -0.01" quat="0.7073883 0 0.7068252 0" solref="0.001 1" type="box" />
                <geom density="100" name="noviz_collision_hole1_5" group="0" pos="0.0 -0.07 -0.01" quat="0.7073883 0 0.7068252 0" rgba="0 0 0 0" size="0.0021 0.00825 0.00825" friction="0.95 0.3 0.2" solref="0.001 1" type="box" />
                <site group="0" name="hole-wire,reach_site1" pos="0.0 -0.07 0.048" rgba="1 1 0 1" size="0.005" />
<!--                <site group="0" name="hole-wire,0,90,180,270,conn_site1" pos="0.0 -0.07 -0.008" rgba="0.9019 0.0980 0.2941 0.3" size="0.005" />-->
<!--                <site name="embed_hole1" pos="0 0 0" rgba="0 0 0 0" size="0.012" />-->
                <site name="composite_hole1_horizontal_radius_site" pos="0.0 -0.07 0" rgba="0 0 0 0" size="0.012" />
            </body>
            <site group="0" name="hole-wire,conn_site1" pos="-0.108 -0.07 0.08825" quat="0.7071408 0 0.7070727 0" rgba="0.9019 0.0980 0.2941 0.3" size="0.005" />


<!--            &lt;!&ndash;Hole 1&ndash;&gt;-->
<!--            <body name="composite_hole1" pos="-0.1 0 0" quat="1 0 0 0">-->
<!--                &lt;!&ndash;Base&ndash;&gt;-->
<!--                <geom conaffinity="0" contype="0" density="0" material="pencil-wood" size="0.03 0.00825 0.00825" name="plat1_geom" group="1" pos="0 -0.07 0.05" quat="0.7073883 0 0.7068252 0" solref="0.001 1" type="box" />-->
<!--                <geom density="100" name="noviz_collision_plat1" group="0" pos="0 -0.07 0.05" quat="0.7073883 0 0.7068252 0" rgba="0 0 0 0" size="0.03 0.00825 0.00825" friction="0.95 0.3 0.2" solref="0.001 1" type="box" />-->
<!--                &lt;!&ndash;Hole&ndash;&gt;-->
<!--                <geom conaffinity="0" contype="0" density="0" material="smetal" size="0.01 0.0016  0.00825" name="hole1_1_geom" group="1" pos="0 -0.07665  0.092" quat="0.7073883 0 0.7068252 0" solref="0.001 1" type="box" />-->
<!--                <geom density="100" name="noviz_collision_hole1_1" group="0" pos="0 -0.07665  0.092" quat="0.7073883 0 0.7068252 0" rgba="0 0 0 0" size="0.01 0.0016  0.00825" friction="0.95 0.3 0.2" solref="0.001 1" type="box" />-->
<!--                <geom conaffinity="0" contype="0" density="0" material="smetal" size="0.01 0.00625 0.0016" name="hole1_2_geom" group="1" pos="-0.00665 -0.07 0.092" quat="0.7073883 0 0.7068252 0" solref="0.001 1" type="box" />-->
<!--                <geom density="100" name="noviz_collision_hole1_2" group="0" pos="-0.0065 -0.07 0.092" quat="0.7073883 0 0.7068252 0" rgba="0 0 0 0" size="0.01 0.00625 0.0016" friction="0.95 0.3 0.2" solref="0.001 1" type="box" />-->
<!--                <geom conaffinity="0" contype="0" density="0" material="smetal" size="0.01 0.00625 0.0016" name="hole1_3_geom" group="1" pos="0.00665 -0.07 0.092" quat="0.7073883 0 0.7068252 0" solref="0.001 1" type="box" />-->
<!--                <geom density="100" name="noviz_collision_hole1_3" group="0" pos="0.00665 -0.07 0.092" quat="0.7073883 0 0.7068252 0" rgba="0 0 0 0" size="0.01 0.00625 0.0016" friction="0.95 0.3 0.2" solref="0.001 1" type="box" />-->
<!--                <geom conaffinity="0" contype="0" density="0" material="smetal" size="0.01 0.0016 0.00825" name="hole1_4_geom" group="1" pos="0 -0.06335 0.092" quat="0.7073883 0 0.7068252 0" solref="0.001 1" type="box" />-->
<!--                <geom density="100" name="noviz_collision_hole1_4" group="0" pos="0 -0.06335 0.092" quat="0.7073883 0 0.7068252 0" rgba="0 0 0 0" size="0.01 0.0016 0.00825" friction="0.95 0.3 0.2" solref="0.001 1" type="box" />-->
<!--                <geom conaffinity="0" contype="0" density="0" material="smetal" size="0.0021 0.00825 0.00825" name="hole1_5_geom" group="1" pos="0 -0.07 0.082" quat="0.7073883 0 0.7068252 0" solref="0.001 1" type="box" />-->
<!--                <geom density="100" name="noviz_collision_hole1_5" group="0" pos="0 -0.07 0.082" quat="0.7073883 0 0.7068252 0" rgba="0 0 0 0" size="0.0021 0.00825 0.00825" friction="0.95 0.3 0.2" solref="0.001 1" type="box" />-->
<!--                <site group="0" name="hole-wire,reach_site1" pos="0 -0.07 0.124" rgba="1 1 0 1" size="0.005" />-->
<!--&lt;!&ndash;                <site group="0" name="hole-wire,conn_site1" pos="0 -0.07 0.084" rgba="0.9019 0.0980 0.2941 0.3" size="0.005" />&ndash;&gt;-->
<!--                <site name="insertion_hole_1_horizontal_radius_site" pos="0 -0.07 0.092" rgba="0 0 0 0" size="0.012" />-->
<!--            </body>-->
<!--            <site group="0" name="hole-wire,conn_site1" pos="-0.1 -0.07 0.084" rgba="0.9019 0.0980 0.2941 0.3" size="0.005" />-->

            <!--Clip 1-->
<!--            <body name="composite_clip1" pos="0.1 -0.005 0.08825" quat="0.7071408 0 0.7070727 0">-->
<!--                &lt;!&ndash; Base&ndash;&gt;-->
<!--                <geom conaffinity="0" contype="0" density="0" material="pencil-wood" size="0.03 0.0132 0.01" name="clip_base1_geom" group="1" pos="0.03825 -0.065 0" quat="1 0 0 0" solref="0.001 1" type="box" />-->
<!--                <geom density="100" name="noviz_collision_clip_base1" group="0" pos="0.03825 -0.065 0" quat="1 0 0 0" rgba="0 0 0 0" size="0.03 0.0132 0.01" friction="0.95 0.3 0.2" solref="0.001 1" type="box" />-->
<!--                &lt;!&ndash; Clip&ndash;&gt;-->
<!--                <geom conaffinity="0" contype="0" density="0" material="smetal" size="0.005 0.0016  0.00825" name="clip1_1_geom" group="1" pos="0.0 -0.07665  0" quat="0.7073883 0 0.7068252 0" solref="0.001 1" type="box" />-->
<!--                <geom density="100" name="noviz_collision_clip1_1" group="0" pos="0.0 -0.07665  0" quat="0.7073883 0 0.7068252 0" rgba="0 0 0 0" size="0.005 0.0016  0.00825" friction="0.95 0.3 0.2" solref="0.001 1" type="box" />-->
<!--&lt;!&ndash;                <geom conaffinity="0" contype="0" density="0" material="smetal" size="0.01 0.00625 0.0016" name="clip1_2_geom" group="1" pos="-0.00665 -0.07 0" quat="0.7073883 0 0.7068252 0" solref="0.001 1" type="box" />&ndash;&gt;-->
<!--&lt;!&ndash;                <geom density="100" name="noviz_collision_clip1_2" group="0" pos="-0.00665 -0.07 0" quat="0.7073883 0 0.7068252 0" rgba="0 0 0 0" size="0.01 0.00625 0.0016" friction="0.95 0.3 0.2" solref="0.001 1" type="box" />&ndash;&gt;-->
<!--                <geom conaffinity="0" contype="0" density="0" material="smetal" size="0.01 0.0132 0.0016" name="clip1_3_geom" group="1" pos="0.00665 -0.065 0" quat="0.7073883 0 0.7068252 0" solref="0.001 1" type="box" />-->
<!--                <geom density="100" name="noviz_collision_clip1_3" group="0" pos="0.00665 -0.065 0" quat="0.7073883 0 0.7068252 0" rgba="0 0 0 0" size="0.01 0.0132 0.0016" friction="0.95 0.3 0.2" solref="0.001 1" type="box" />-->
<!--                <geom conaffinity="0" contype="0" density="0" material="smetal" size="0.005 0.0016 0.00825" name="clip1_4_geom" group="1" pos="0.0 -0.05335 0" quat="0.7073883 0 0.7068252 0" solref="0.001 1" type="box" />-->
<!--                <geom density="100" name="noviz_collision_clip1_4" group="0" pos="0.0 -0.05335 0" quat="0.7073883 0 0.7068252 0" rgba="0 0 0 0" size="0.005 0.0016 0.00825" friction="0.95 0.3 0.2" solref="0.001 1" type="box" />-->
<!--&lt;!&ndash;                <geom conaffinity="0" contype="0" density="0" material="smetal" size="0.0021 0.00825 0.00825" name="clip1_5_geom" group="1" pos="0.0 -0.07 -0.01" quat="0.7073883 0 0.7068252 0" solref="0.001 1" type="box" />&ndash;&gt;-->
<!--&lt;!&ndash;                <geom density="100" name="noviz_collision_clip1_5" group="0" pos="0.0 -0.07 -0.01" quat="0.7073883 0 0.7068252 0" rgba="0 0 0 0" size="0.0021 0.00825 0.00825" friction="0.95 0.3 0.2" solref="0.001 1" type="box" />&ndash;&gt;-->
<!--                <site group="0" name="clip-wire,0,90,180,270,conn_site1" pos="0.0 -0.065 -0.008" rgba="0.9019 0.0980 0.2941 0.3" size="0.005" />-->
<!--                <site name="insertion_clip_1_horizontal_radius_site" pos="0.0 -0.065 0" rgba="0 0 0 0" size="0.012" />-->
<!--            </body>-->

<!--            &lt;!&ndash;Clip 2&ndash;&gt;-->
<!--            <body name="composite_clip2" pos="0.15 0 0.08825" quat="0.7071408 0 0.7070727 0">-->
<!--                &lt;!&ndash; Base&ndash;&gt;-->
<!--                <geom conaffinity="0" contype="0" density="0" material="pencil-wood" size="0.03 0.00825 0.01" name="clip_base2_geom" group="1" pos="0.03825 -0.07 0" quat="1 0 0 0" solref="0.001 1" type="box" />-->
<!--                <geom density="100" name="noviz_collision_clip_base2" group="0" pos="0.03825 -0.07 0" quat="1 0 0 0" rgba="0 0 0 0" size="0.03 0.00825 0.01" friction="0.95 0.3 0.2" solref="0.001 1" type="box" />-->
<!--                &lt;!&ndash; Clip&ndash;&gt;-->
<!--                <geom conaffinity="0" contype="0" density="0" material="smetal" size="0.005 0.0016  0.00825" name="clip2_1_geom" group="1" pos="0.0 -0.07665  0" quat="0.7073883 0 0.7068252 0" solref="0.001 1" type="box" />-->
<!--                <geom density="100" name="noviz_collision_clip2_1" group="0" pos="0.0 -0.07665  0" quat="0.7073883 0 0.7068252 0" rgba="0 0 0 0" size="0.005 0.0016  0.00825" friction="0.95 0.3 0.2" solref="0.001 1" type="box" />-->
<!--                <geom conaffinity="0" contype="0" density="0" material="smetal" size="0.01 0.0125 0.0016" name="clip2_3_geom" group="1" pos="0.00665 -0.065 0" quat="0.7073883 0 0.7068252 0" solref="0.001 1" type="box" />-->
<!--                <geom density="100" name="noviz_collision_clip2_3" group="0" pos="0.00665 -0.065 0" quat="0.7073883 0 0.7068252 0" rgba="0 0 0 0" size="0.01 0.0125 0.0016" friction="0.95 0.3 0.2" solref="0.001 1" type="box" />-->
<!--                <geom conaffinity="0" contype="0" density="0" material="smetal" size="0.005 0.0016 0.00825" name="clip2_4_geom" group="1" pos="0.0 -0.05335 0" quat="0.7073883 0 0.7068252 0" solref="0.001 1" type="box" />-->
<!--                <geom density="100" name="noviz_collision_clip2_4" group="0" pos="0.0 -0.05335 0" quat="0.7073883 0 0.7068252 0" rgba="0 0 0 0" size="0.005 0.0016 0.00825" friction="0.95 0.3 0.2" solref="0.001 1" type="box" />-->
<!--&lt;!&ndash;                <geom conaffinity="0" contype="0" density="0" material="smetal" size="0.0021 0.00825 0.00825" name="clip1_5_geom" group="1" pos="0.0 -0.07 -0.01" quat="0.7073883 0 0.7068252 0" solref="0.001 1" type="box" />&ndash;&gt;-->
<!--&lt;!&ndash;                <geom density="100" name="noviz_collision_clip1_5" group="0" pos="0.0 -0.07 -0.01" quat="0.7073883 0 0.7068252 0" rgba="0 0 0 0" size="0.0021 0.00825 0.00825" friction="0.95 0.3 0.2" solref="0.001 1" type="box" />&ndash;&gt;-->
<!--                <site group="0" name="clip-wire,0,90,180,270,conn_site2" pos="0.0 -0.065 -0.008" rgba="0.9019 0.0980 0.2941 0.3" size="0.005" />-->
<!--                <site name="insertion_clip_2_horizontal_radius_site" pos="0.0 -0.065 0" rgba="0 0 0 0" size="0.012" />-->
<!--            </body>-->
        </body>

<!--        <body pos="0.0 -0.2 0.4" name="shelf">-->
<!--            <site name="shelf_horizontal_radius_site" pos="0.0 0.0 0.0" rgba="1 1 0 1" size="0.03" />-->
<!--&lt;!&ndash;            <geom size="0.02 0.02 0.1" type="box" mass="2000" group="0" name="noviz_collision_z_leg0" friction="1 0.005 0.0001"/>&ndash;&gt;-->
<!--&lt;!&ndash;            <geom size="0.02 0.02 0.1" type="box" mass="1e-8" conaffinity="0" contype="0" group="1" name="z_leg0_visual" material="smetal"/>&ndash;&gt;-->
<!--&lt;!&ndash;            <site name="z_leg0_horizontal_radius_site" pos="0.0 0.0 0.0" rgba="1 1 0 1" size="0.03" />&ndash;&gt;-->
<!--&lt;!&ndash;            &lt;!&ndash; z_leg1 &ndash;&gt;&ndash;&gt;-->
<!--&lt;!&ndash;            <geom pos="0.0 0.0 0.2" size="0.02 0.02 0.1" type="box" mass="2000" group="0" name="noviz_collision_z_leg1" friction="1 0.005 0.0001"/>&ndash;&gt;-->
<!--&lt;!&ndash;            <geom pos="0.0 0.0 0.2" size="0.02 0.02 0.1" type="box" mass="1e-8" conaffinity="0" contype="0" group="1" name="z_leg1_visual" material="smetal"/>&ndash;&gt;-->
<!--&lt;!&ndash;            &lt;!&ndash; x_leg2 &ndash;&gt;&ndash;&gt;-->
<!--&lt;!&ndash;            <geom pos="0.08 0.0 0.1" size="0.1 0.02 0.02" type="box" mass="2000" group="0" name="leg2_collision" friction="1 0.005 0.0001"/>&ndash;&gt;-->
<!--&lt;!&ndash;            <geom pos="0.08 0.0 0.1" size="0.1 0.02 0.02" type="box" mass="1e-8" conaffinity="0" contype="0" group="1" name="leg2_visual" material="smetal"/>&ndash;&gt;-->
<!--&lt;!&ndash;            &lt;!&ndash; y_leg8 &ndash;&gt;&ndash;&gt;-->
<!--&lt;!&ndash;            <geom size="0.02 0.1 0.02" type="box" mass="2000" group="0" name="leg8_collision" friction="1 0.005 0.0001"/>&ndash;&gt;-->
<!--&lt;!&ndash;            <geom size="0.02 0.1 0.02" type="box" mass="1e-8" conaffinity="0" contype="0" group="1" name="leg8_visual" material="smetal"/>&ndash;&gt;-->
<!--&lt;!&ndash;            &lt;!&ndash; x_leg3 &ndash;&gt;&ndash;&gt;-->
<!--&lt;!&ndash;            <geom size="0.1 0.02 0.02" type="box" mass="2000" group="0" name="leg3_collision" friction="1 0.005 0.0001"/>&ndash;&gt;-->
<!--&lt;!&ndash;            <geom size="0.1 0.02 0.02" type="box" mass="1e-8" conaffinity="0" contype="0" group="1" name="leg3_visual" material="smetal"/>&ndash;&gt;-->
<!--&lt;!&ndash;            &lt;!&ndash; x_leg4 &ndash;&gt;&ndash;&gt;-->
<!--&lt;!&ndash;            <geom size="0.1 0.02 0.02" type="box" mass="2000" group="0" name="leg4_collision" friction="1 0.005 0.0001"/>&ndash;&gt;-->
<!--&lt;!&ndash;            <geom size="0.1 0.02 0.02" type="box" mass="1e-8" conaffinity="0" contype="0" group="1" name="leg4_visual" material="smetal"/>&ndash;&gt;-->
<!--&lt;!&ndash;            &lt;!&ndash; y_leg9 &ndash;&gt;&ndash;&gt;-->
<!--            <body pos="0.0 0.0 0.0" name="composite_z_leg0">-->
<!--                <geom size="0.02 0.02 0.1" type="box" mass="2000" group="0" name="noviz_collision_z_leg0" friction="1 0.005 0.0001"/>-->
<!--                <geom size="0.02 0.02 0.1" type="box" mass="1e-8" conaffinity="0" contype="0" group="1" name="z_leg0_visual" material="smetal"/>-->
<!--                    <body pos="0.0 0.0 0.2" name="composite_z_leg1">-->
<!--                        <geom size="0.02 0.02 0.1" type="box" mass="2000" group="0" name="noviz_collision_z_leg1" friction="1 0.005 0.0001"/>-->
<!--			            <geom size="0.02 0.02 0.1" type="box" mass="1e-8" conaffinity="0" contype="0" group="1" name="z_leg1_visual" material="smetal"/>-->
<!--                        <site name="z_leg1_horizontal_radius_site" pos="0.0 0.0 0.0" rgba="1 1 0 1" size="0.03" />-->
<!--&lt;!&ndash;                        <body pos="0.08 0.0 0.1" name="composite_x_leg2">&ndash;&gt;-->
<!--&lt;!&ndash;                            <geom size="0.1 0.02 0.02" type="box" mass="2000" group="0" name="leg2_collision" friction="1 0.005 0.0001"/>&ndash;&gt;-->
<!--&lt;!&ndash;			                <geom size="0.1 0.02 0.02" type="box" mass="1e-8" conaffinity="0" contype="0" group="1" name="leg2_visual" material="smetal"/>&ndash;&gt;-->
<!--&lt;!&ndash;                            <body pos="0.1 0.08 0.0" name="composite_y_leg8">&ndash;&gt;-->
<!--&lt;!&ndash;                                <geom size="0.02 0.1 0.02" type="box" mass="2000" group="0" name="leg8_collision" friction="1 0.005 0.0001"/>&ndash;&gt;-->
<!--&lt;!&ndash;			                    <geom size="0.02 0.1 0.02" type="box" mass="1e-8" conaffinity="0" contype="0" group="1" name="leg8_visual" material="smetal"/>&ndash;&gt;-->
<!--&lt;!&ndash;                            </body>&ndash;&gt;-->
<!--&lt;!&ndash;                            <body pos="0.2 0.0 0.0" name="composite_x_leg3">&ndash;&gt;-->
<!--&lt;!&ndash;                                <geom size="0.1 0.02 0.02" type="box" mass="2000" group="0" name="leg3_collision" friction="1 0.005 0.0001"/>&ndash;&gt;-->
<!--&lt;!&ndash;			                    <geom size="0.1 0.02 0.02" type="box" mass="1e-8" conaffinity="0" contype="0" group="1" name="leg3_visual" material="smetal"/>&ndash;&gt;-->
<!--&lt;!&ndash;                                <body pos="0.2 0.0 0.0" name="composite_x_leg4">&ndash;&gt;-->
<!--&lt;!&ndash;                                    <geom size="0.1 0.02 0.02" type="box" mass="2000" group="0" name="leg4_collision" friction="1 0.005 0.0001"/>&ndash;&gt;-->
<!--&lt;!&ndash;			                        <geom size="0.1 0.02 0.02" type="box" mass="1e-8" conaffinity="0" contype="0" group="1" name="leg4_visual" material="smetal"/>&ndash;&gt;-->
<!--&lt;!&ndash;                                    <body pos="0.1 0.08 0.0" name="composite_y_leg9">&ndash;&gt;-->
<!--&lt;!&ndash;                                        <geom size="0.02 0.1 0.02" type="box" mass="2000" group="0" name="leg9_collision" friction="1 0.005 0.0001"/>&ndash;&gt;-->
<!--&lt;!&ndash;			                            <geom size="0.02 0.1 0.02" type="box" mass="1e-8" conaffinity="0" contype="0" group="1" name="leg9_visual" material="smetal"/>&ndash;&gt;-->
<!--&lt;!&ndash;                                    </body>&ndash;&gt;-->
<!--&lt;!&ndash;                                    <body pos="0.2 0.0 0.0" name="composite_x_leg5">&ndash;&gt;-->
<!--&lt;!&ndash;                                        <geom size="0.1 0.02 0.02" type="box" mass="2000" group="0" name="leg5_collision" friction="1 0.005 0.0001"/>&ndash;&gt;-->
<!--&lt;!&ndash;			                            <geom size="0.1 0.02 0.02" type="box" mass="1e-8" conaffinity="0" contype="0" group="1" name="leg5_visual" material="smetal"/>&ndash;&gt;-->
<!--&lt;!&ndash;                                        <body pos="0.08 0.0 -0.1" name="composite_z_leg6">&ndash;&gt;-->
<!--&lt;!&ndash;                                            <geom size="0.02 0.02 0.1" type="box" mass="2000" group="0" name="leg6_collision" friction="1 0.005 0.0001"/>&ndash;&gt;-->
<!--&lt;!&ndash;                                            <geom size="0.02 0.02 0.1" type="box" mass="1e-8" conaffinity="0" contype="0" group="1" name="leg6_visual" material="smetal"/>&ndash;&gt;-->
<!--&lt;!&ndash;                                            <body pos="0.0 0.0 -0.2" name="composite_z_leg7">&ndash;&gt;-->
<!--&lt;!&ndash;                                                <geom size="0.02 0.02 0.1" type="box" mass="2000" group="0" name="leg7_collision" friction="1 0.005 0.0001"/>&ndash;&gt;-->
<!--&lt;!&ndash;                                                <geom size="0.02 0.02 0.1" type="box" mass="1e-8" conaffinity="0" contype="0" group="1" name="leg7_visual" material="smetal"/>&ndash;&gt;-->
<!--&lt;!&ndash;                                            </body>&ndash;&gt;-->
<!--&lt;!&ndash;                                        </body>&ndash;&gt;-->
<!--&lt;!&ndash;                                    </body>&ndash;&gt;-->
<!--&lt;!&ndash;                                </body>&ndash;&gt;-->
<!--&lt;!&ndash;                            </body>&ndash;&gt;-->
<!--&lt;!&ndash;                        </body>&ndash;&gt;-->
<!--                    </body>-->
<!--                </body>-->
<!--        </body>-->

<!--            panel-->
<!--            <body pos="-0.03 0.0 0.45" quat="1  0 0  0" name="panel0">-->
<!--&lt;!&ndash;            <body pos="0.0 0.0 0.20025" quat="0 0 -0.7068252 0.7073883" name="panel0">&ndash;&gt;-->
<!--                <geom size="0.3 0.15 0.005" type="box" group="0" name="panel_collision" />-->
<!--                <geom size="0.3 0.15 0.005" type="box" conaffinity="0" contype="0" group="1" name="panel_visual" material="table_mat"/>-->
<!--                <body name="wire_clip_1" pos="0.0 0.05 0.00875">-->
<!--                    <geom name="square_nut_1_top" pos="0 -0.00665  0" size="0.006 0.0021  0.00875 " type="box" solimp="0.998 0.998 0.001" solref="0.02 1" density="100" friction="0.95 0.3 0.2" group="0" condim="3"/>-->
<!--                    <geom name="square_nut_1_top_visual" pos="0 -0.00665  0" size="0.006 0.0021  0.00875 " type="box" conaffinity="0" contype="0" group="1" material="pencil-wood" />-->
<!--&lt;!&ndash;                    <geom pos="0.0 0 -0.00665" size="0.006 0.00625 0.0021 " type="box" solimp="0.998 0.998 0.001" solref="0.02 1" density="100" friction="0.95 0.3 0.1" group="0" condim="4" material="smetal" />&ndash;&gt;-->
<!--&lt;!&ndash;                    <geom pos="0.0 0 0.00665" size="0.006 0.00625 0.0021 " type="box" solimp="0.998 0.998 0.001" solref="0.02 1" density="100" friction="0.95 0.3 0.1" group="0" condim="3" material="smetal" />&ndash;&gt;-->
<!--                    <geom pos="0 0.00665 0" size="0.006 0.0021 0.00875 " type="box" solimp="0.998 0.998 0.001" solref="0.02 1" density="100" friction="0.95 0.3 0.1" group="0" condim="3"/>-->
<!--&lt;!&ndash;                   <site rgba="1 0 0 1" size="0.001" pos="0.0108 0 0" name="handle_site"/>&ndash;&gt;-->
<!--&lt;!&ndash;                    <site rgba="1 0 0 1" size="0.0006" pos="0 0 0" name="center_site"/>&ndash;&gt;-->
<!--                </body>-->
<!--&lt;!&ndash;                <body name="wire_clip_2" pos="-0.12 -0.07 0.00875">&ndash;&gt;-->
<!--&lt;!&ndash;                    <geom pos="0 -0.00665  0" size="0.006 0.0021  0.00875 " type="box" solimp="0.998 0.998 0.001" solref="0.02 1" density="100" friction="0.95 0.3 0.2" group="0" condim="4" material="pencil-wood" />&ndash;&gt;-->
<!--&lt;!&ndash;&lt;!&ndash;                    <geom pos="0.0 0 -0.00665" size="0.006 0.00625 0.0021 " type="box" solimp="0.998 0.998 0.001" solref="0.02 1" density="100" friction="0.95 0.3 0.1" group="0" condim="4" material="smetal" />&ndash;&gt;&ndash;&gt;-->
<!--&lt;!&ndash;&lt;!&ndash;                    <geom pos="0.0 0 0.00665" size="0.006 0.00625 0.0021 " type="box" solimp="0.998 0.998 0.001" solref="0.02 1" density="100" friction="0.95 0.3 0.1" group="0" condim="4" material="smetal" />&ndash;&gt;&ndash;&gt;-->
<!--&lt;!&ndash;                    <geom pos="0 0.00665 0" size="0.006 0.0021 0.00875 " type="box" solimp="0.998 0.998 0.001" solref="0.02 1" density="100" friction="0.95 0.3 0.1" group="0" condim="4" material="pencil-wood" />&ndash;&gt;-->
<!--&lt;!&ndash;&lt;!&ndash;                    <site rgba="1 0 0 1" size="0.001" pos="0.0108 0 0" name="handle_site"/>&ndash;&gt;&ndash;&gt;-->
<!--&lt;!&ndash;&lt;!&ndash;                    <site rgba="1 0 0 1" size="0.0006" pos="0 0 0" name="center_site"/>&ndash;&gt;&ndash;&gt;-->
<!--&lt;!&ndash;                </body>&ndash;&gt;-->
<!--&lt;!&ndash;                <body name="wire_clip_3" pos="0.1 0.05 0.00875">&ndash;&gt;-->
<!--&lt;!&ndash;                    <geom pos="0 -0.00665  0" size="0.006 0.0021  0.00875 " type="box" solimp="0.998 0.998 0.001" solref="0.02 1" density="100" friction="0.95 0.3 0.2" group="0" condim="4" material="pencil-wood" />&ndash;&gt;-->
<!--&lt;!&ndash;&lt;!&ndash;                    <geom pos="0.0 0 -0.00665" size="0.006 0.00625 0.0021 " type="box" solimp="0.998 0.998 0.001" solref="0.02 1" density="100" friction="0.95 0.3 0.1" group="0" condim="4" material="smetal" />&ndash;&gt;&ndash;&gt;-->
<!--&lt;!&ndash;&lt;!&ndash;                    <geom pos="0.0 0 0.00665" size="0.006 0.00625 0.0021 " type="box" solimp="0.998 0.998 0.001" solref="0.02 1" density="100" friction="0.95 0.3 0.1" group="0" condim="4" material="smetal" />&ndash;&gt;&ndash;&gt;-->
<!--&lt;!&ndash;                    <geom pos="0 0.00665 0" size="0.006 0.0021 0.00875 " type="box" solimp="0.998 0.998 0.001" solref="0.02 1" density="100" friction="0.95 0.3 0.1" group="0" condim="4" material="pencil-wood" />&ndash;&gt;-->
<!--&lt;!&ndash;&lt;!&ndash;                    <site rgba="1 0 0 1" size="0.001" pos="0.0108 0 0" name="handle_site"/>&ndash;&gt;&ndash;&gt;-->
<!--&lt;!&ndash;&lt;!&ndash;                    <site rgba="1 0 0 1" size="0.0006" pos="0 0 0" name="center_site"/>&ndash;&gt;&ndash;&gt;-->
<!--&lt;!&ndash;                </body>&ndash;&gt;-->
<!--&lt;!&ndash;                <body name="insertation_hole_0" pos="-0.25 -0.07 0.00875" quat="0.7073883 0 -0.7068252 0">&ndash;&gt;-->
<!--&lt;!&ndash;                    <geom pos="0 -0.00665  0" size="0.008 0.00365  0.00875 " type="box" solimp="0.998 0.998 0.001" solref="0.02 1" density="100" friction="0.95 0.3 0.2" group="0" condim="4" material="bmetal" />&ndash;&gt;-->
<!--&lt;!&ndash;&lt;!&ndash;                    <geom pos="0.0 0 -0.00665" size="0.008 0.00625 0.0021 " type="box" solimp="0.998 0.998 0.001" solref="0.02 1" density="100" friction="0.95 0.3 0.1" group="0" condim="4" material="smetal" />&ndash;&gt;&ndash;&gt;-->
<!--&lt;!&ndash;                    <geom pos="0.0 0 0.00665" size="0.008 0.00625 0.0021 " type="box" solimp="0.998 0.998 0.001" solref="0.02 1" density="100" friction="0.95 0.3 0.1" group="0" condim="4" material="bmetal" />&ndash;&gt;-->
<!--&lt;!&ndash;                    <geom pos="0 0.00665 0" size="0.008 0.00365 0.00875 " type="box" solimp="0.998 0.998 0.001" solref="0.02 1" density="100" friction="0.95 0.3 0.1" group="0" condim="4" material="bmetal" />&ndash;&gt;-->
<!--&lt;!&ndash;&lt;!&ndash;                    <geom pos="0.008 0 0" size="0.0021 0.00875 0.00875 " type="box" solimp="0.998 0.998 0.001" solref="0.02 1" density="100" friction="0.95 0.3 0.1" group="0" condim="4" material="bmetal" />&ndash;&gt;&ndash;&gt;-->
<!--&lt;!&ndash;&lt;!&ndash;                    <site rgba="1 0 0 1" size="0.001" pos="0.0108 0 0" name="handle_site"/>&ndash;&gt;&ndash;&gt;-->
<!--&lt;!&ndash;&lt;!&ndash;                    <site rgba="1 0 0 1" size="0.0006" pos="0 0 0" name="center_site"/>&ndash;&gt;&ndash;&gt;-->
<!--&lt;!&ndash;&lt;!&ndash;                    <body name="wire1" pos="-0.007 0.0 0.0" quat="0 0 1 0">&ndash;&gt;&ndash;&gt;-->
<!--&lt;!&ndash;&lt;!&ndash;                        <include file="assets/rope_expanded_short.xml"/>&ndash;&gt;&ndash;&gt;-->
<!--&lt;!&ndash;&lt;!&ndash;                    </body>&ndash;&gt;&ndash;&gt;-->
<!--&lt;!&ndash;                </body>&ndash;&gt;-->
<!--&lt;!&ndash;                <body name="insertation_hole_1" pos="0.2 0.05 0.00875">&ndash;&gt;-->
<!--&lt;!&ndash;                    <geom pos="0 -0.00665  0" size="0.008 0.00365  0.00875 " type="box" solimp="0.998 0.998 0.001" solref="0.02 1" density="100" friction="0.95 0.3 0.2" group="0" condim="4" material="bmetal" />&ndash;&gt;-->
<!--&lt;!&ndash;&lt;!&ndash;                    <geom pos="0.0 0 -0.00665" size="0.006 0.00625 0.0021 " type="box" solimp="0.998 0.998 0.001" solref="0.02 1" density="100" friction="0.95 0.3 0.1" group="0" condim="4" material="smetal" />&ndash;&gt;&ndash;&gt;-->
<!--&lt;!&ndash;                    <geom pos="0.0 0 0.00665" size="0.008 0.00625 0.0021 " type="box" solimp="0.998 0.998 0.001" solref="0.02 1" density="100" friction="0.95 0.3 0.1" group="0" condim="4" material="bmetal" />&ndash;&gt;-->
<!--&lt;!&ndash;                    <geom pos="0 0.00665 0" size="0.008 0.00365 0.00875 " type="box" solimp="0.998 0.998 0.001" solref="0.02 1" density="100" friction="0.95 0.3 0.1" group="0" condim="4" material="bmetal" />&ndash;&gt;-->
<!--&lt;!&ndash;                    <geom pos="0.008 0 0" size="0.0021 0.00875 0.00875 " type="box" solimp="0.998 0.998 0.001" solref="0.02 1" density="100" friction="0.95 0.3 0.1" group="0" condim="4" material="bmetal" />&ndash;&gt;-->
<!--&lt;!&ndash;&lt;!&ndash;                    <site rgba="1 0 0 1" size="0.001" pos="0.0108 0 0" name="handle_site"/>&ndash;&gt;&ndash;&gt;-->
<!--&lt;!&ndash;&lt;!&ndash;                    <site rgba="1 0 0 1" size="0.0006" pos="0 0 0" name="center_site"/>&ndash;&gt;&ndash;&gt;-->
<!--&lt;!&ndash;                </body>&ndash;&gt;-->
<!--&lt;!&ndash;                <body name="insertation_hole_2" pos="-0.25 0.07 0.00875" quat="0.7073883 0 0 0.7068252">&ndash;&gt;-->
<!--&lt;!&ndash;                    <geom pos="0 -0.00665  0" size="0.008 0.00365  0.00875 " type="box" solimp="0.998 0.998 0.001" solref="0.02 1" density="100" friction="0.95 0.3 0.2" group="0" condim="4" material="bmetal" />&ndash;&gt;-->
<!--&lt;!&ndash;&lt;!&ndash;                    <geom pos="0.0 0 -0.00665" size="0.006 0.00625 0.0021 " type="box" solimp="0.998 0.998 0.001" solref="0.02 1" density="100" friction="0.95 0.3 0.1" group="0" condim="4" material="smetal" />&ndash;&gt;&ndash;&gt;-->
<!--&lt;!&ndash;                    <geom pos="0.0 0 0.00665" size="0.008 0.00625 0.0021 " type="box" solimp="0.998 0.998 0.001" solref="0.02 1" density="100" friction="0.95 0.3 0.1" group="0" condim="4" material="bmetal" />&ndash;&gt;-->
<!--&lt;!&ndash;                    <geom pos="0 0.00665 0" size="0.008 0.00365 0.00875 " type="box" solimp="0.998 0.998 0.001" solref="0.02 1" density="100" friction="0.95 0.3 0.1" group="0" condim="4" material="bmetal" />&ndash;&gt;-->
<!--&lt;!&ndash;                    <geom pos="0.008 0 0" size="0.0021 0.00875 0.00875 " type="box" solimp="0.998 0.998 0.001" solref="0.02 1" density="100" friction="0.95 0.3 0.1" group="0" condim="4" material="bmetal" />&ndash;&gt;-->
<!--&lt;!&ndash;&lt;!&ndash;                    <site rgba="1 0 0 1" size="0.001" pos="0.0108 0 0" name="handle_site"/>&ndash;&gt;&ndash;&gt;-->
<!--&lt;!&ndash;&lt;!&ndash;                    <site rgba="1 0 0 1" size="0.0006" pos="0 0 0" name="center_site"/>&ndash;&gt;&ndash;&gt;-->
<!--&lt;!&ndash;                </body>&ndash;&gt;-->
<!--            </body>-->


        <!--Hole-->
<!--        <body name="insertion_hole_1" pos="0.2 0.07 0.032" quat="0.7073883 0 0.7068252 0">-->
<!--        <body name="insertion_hole_1" pos="0.1 -0.032 -0.06998405" quat="0.7073883 0 0 0.7068252">-->
<!--            <geom conaffinity="0" contype="0" density="0" material="smetal" size="0.01 0.0032  0.00875" name="hole1_1_geom" pos="0 -0.00665  0" solref="0.001 1" type="box" />-->
<!--            <geom density="100" name="noviz_collision_hole1_1" pos="0 -0.00665  0" quat="1 0 0 0" rgba="0 0 0 0" size="0.01 0.0032  0.00875" friction="0.95 0.3 0.2" solref="0.001 1" type="box" />-->
<!--            <geom  pos="0 -0.00665  0" size="0.01 0.0032  0.00875 " type="box" solimp="0.998 0.998 0.001" solref="0.02 1" density="100" friction="0.95 0.3 0.2" group="0" condim="4" material="smetal" />-->
<!--&lt;!&ndash;            <geom conaffinity="0" contype="0" density="0" material="smetal" size="0.01 0.00625 0.0031" name="hole1_2_geom" pos="0.0 0 -0.00665" solref="0.001 1" type="box" />&ndash;&gt;-->
<!--&lt;!&ndash;            <geom density="100" name="noviz_collision_hole1_2" pos="0.0 0 -0.00665" quat="1 0 0 0" rgba="0 0 0 0" size="0.01 0.00625 0.0031" friction="0.95 0.3 0.2" solref="0.001 1" type="box" />&ndash;&gt;-->
<!--            <geom pos="0.0 0 -0.00665" size="0.01 0.00625 0.0031 " type="box" solimp="0.998 0.998 0.001" solref="0.02 1" density="100" friction="0.95 0.3 0.1" group="0" condim="4" material="smetal" />-->
<!--&lt;!&ndash;            <geom conaffinity="0" contype="0" density="0" material="smetal" size="0.01 0.00625 0.0031" name="hole1_3_geom" pos="0.0 0 -0.00665" solref="0.001 1" type="box" />&ndash;&gt;-->
<!--&lt;!&ndash;            <geom density="100" name="noviz_collision_hole1_3" pos="0.0 0 -0.00665" quat="1 0 0 0" rgba="0 0 0 0" size="0.01 0.00625 0.0031" friction="0.95 0.3 0.2" solref="0.001 1" type="box" />&ndash;&gt;-->
<!--            <geom pos="0.0 0 0.00665" size="0.01 0.00625 0.0031 " type="box" solimp="0.998 0.998 0.001" solref="0.02 1" density="100" friction="0.95 0.3 0.1" group="0" condim="4" material="smetal" />-->
<!--&lt;!&ndash;            <geom conaffinity="0" contype="0" density="0" material="smetal" size="0.01 0.0032 0.00875" name="hole1_4_geom" pos="0 0.00665 0" solref="0.001 1" type="box" />&ndash;&gt;-->
<!--&lt;!&ndash;            <geom density="100" name="noviz_collision_hole1_4" pos="0 0.00665 0" quat="1 0 0 0" rgba="0 0 0 0" size="0.01 0.0032 0.00875" friction="0.95 0.3 0.2" solref="0.001 1" type="box" />&ndash;&gt;-->
<!--            <geom pos="0 0.00665 0" size="0.01 0.0032 0.00875 " type="box" solimp="0.998 0.998 0.001" solref="0.02 1" density="100" friction="0.95 0.3 0.1" group="0" condim="4" material="smetal" />-->
<!--&lt;!&ndash;            <geom conaffinity="0" contype="0" density="0" material="smetal" size="0.0021 0.00875 0.00875" name="hole1_5_geom" pos="0.01 0 0" solref="0.001 1" type="box" />&ndash;&gt;-->
<!--&lt;!&ndash;            <geom density="100" name="noviz_collision_hole1_5" pos="0.01 0 0" quat="1 0 0 0" rgba="0 0 0 0" size="0.0021 0.00875 0.00875" friction="0.95 0.3 0.2" solref="0.001 1" type="box" />&ndash;&gt;-->
<!--            <geom pos="0.01 0 0" size="0.0021 0.00875 0.00875 " type="box" solimp="0.998 0.998 0.001" solref="0.02 1" density="100" friction="0.95 0.3 0.1" group="0" condim="4" material="smetal" />-->
<!--            <site group="0" name="hole-wire,0,90,180,270,conn_site1" pos="0.008 0 0" rgba="0.9019 0.0980 0.2941 0.3" size="0.005" />-->
<!--            <site name="insertion_hole_3_horizontal_radius_site" pos="0.0 0.0 0.0" rgba="0 0 0 0" size="0.012" />-->
<!--&lt;!&ndash;              <site rgba="1 0 0 1" size="0.001" pos="0.0108 0 0" name="handle_site"/>&ndash;&gt;-->
<!--&lt;!&ndash;              <site rgba="1 0 0 1" size="0.0006" pos="0 0 0" name="center_site"/>&ndash;&gt;-->
<!--        </body>-->

<!--        <body name="insertion_hole_1" pos="0.1 -0.07 0.032" quat="0.7073883 0 0.7068252 0">-->
<!--&lt;!&ndash;        <body name="insertion_hole_1" pos="0.1 -0.032 -0.06998405" quat="0.7073883 0 0 0.7068252">&ndash;&gt;-->
<!--            <geom conaffinity="0" contype="0" density="0" material="smetal" size="0.01 0.0016  0.00825" name="hole1_1_geom" pos="0 -0.00665  0" solref="0.001 1" type="box" />-->
<!--            <geom density="100" name="noviz_collision_hole1_1" pos="0 -0.00665  0" quat="1 0 0 0" rgba="0 0 0 0" size="0.01 0.0016  0.00825" friction="0.95 0.3 0.2" solref="0.001 1" type="box" />-->
<!--&lt;!&ndash;            <geom  pos="0 -0.00665  0" size="0.01 0.0016  0.00825" type="box" solimp="0.998 0.998 0.001" solref="0.02 1" density="100" friction="0.95 0.3 0.2" group="0" condim="4" material="smetal" />&ndash;&gt;-->
<!--            <geom conaffinity="0" contype="0" density="0" material="smetal" size="0.01 0.00625 0.0016" name="hole1_2_geom" pos="0.0 0 -0.00665" solref="0.001 1" type="box" />-->
<!--            <geom density="100" name="noviz_collision_hole1_2" pos="0.0 0 -0.00665" quat="1 0 0 0" rgba="0 0 0 0" size="0.01 0.00625 0.0016" friction="0.95 0.3 0.2" solref="0.001 1" type="box" />-->
<!--&lt;!&ndash;            <geom pos="0.0 0 -0.00665" size="0.01 0.00625 0.0016 " type="box" solimp="0.998 0.998 0.001" solref="0.02 1" density="100" friction="0.95 0.3 0.1" group="0" condim="4" material="smetal" />&ndash;&gt;-->
<!--            <geom conaffinity="0" contype="0" density="0" material="smetal" size="0.01 0.00625 0.0016" name="hole1_3_geom" pos="0.0 0 0.00665" solref="0.001 1" type="box" />-->
<!--            <geom density="100" name="noviz_collision_hole1_3" pos="0.0 0 0.00665" quat="1 0 0 0" rgba="0 0 0 0" size="0.01 0.00625 0.0016" friction="0.95 0.3 0.2" solref="0.001 1" type="box" />-->
<!--&lt;!&ndash;            <geom pos="0.0 0 0.00665" size="0.01 0.00625 0.0016 " type="box" solimp="0.998 0.998 0.001" solref="0.02 1" density="100" friction="0.95 0.3 0.1" group="0" condim="4" material="smetal" />&ndash;&gt;-->
<!--            <geom conaffinity="0" contype="0" density="0" material="smetal" size="0.01 0.0016 0.00825" name="hole1_4_geom" pos="0 0.00665 0" solref="0.001 1" type="box" />-->
<!--            <geom density="100" name="noviz_collision_hole1_4" pos="0 0.00665 0" quat="1 0 0 0" rgba="0 0 0 0" size="0.01 0.0016 0.00825" friction="0.95 0.3 0.2" solref="0.001 1" type="box" />-->
<!--&lt;!&ndash;            <geom pos="0 0.00665 0" size="0.01 0.0016 0.00825 " type="box" solimp="0.998 0.998 0.001" solref="0.02 1" density="100" friction="0.95 0.3 0.1" group="0" condim="4" material="smetal" />&ndash;&gt;-->
<!--            <geom conaffinity="0" contype="0" density="0" material="smetal" size="0.0021 0.00825 0.00825" name="hole1_5_geom" pos="0.01 0 0" solref="0.001 1" type="box" />-->
<!--            <geom density="100" name="noviz_collision_hole1_5" pos="0.01 0 0" quat="1 0 0 0" rgba="0 0 0 0" size="0.0021 0.00825 0.00825" friction="0.95 0.3 0.2" solref="0.001 1" type="box" />-->
<!--&lt;!&ndash;            <geom pos="0.01 0 0" size="0.0021 0.00825 0.00825 " type="box" solimp="0.998 0.998 0.001" solref="0.02 1" density="100" friction="0.95 0.3 0.1" group="0" condim="4" material="smetal" />&ndash;&gt;-->
<!--            <site group="0" name="hole-wire,0,90,180,270,conn_site1" pos="0.008 0 0" rgba="0.9019 0.0980 0.2941 0.3" size="0.005" />-->
<!--            <site name="insertion_hole_1_horizontal_radius_site" pos="0.0 0.0 0.0" rgba="0 0 0 0" size="0.012" />-->
<!--&lt;!&ndash;              <site rgba="1 0 0 1" size="0.001" pos="0.0108 0 0" name="handle_site"/>&ndash;&gt;-->
<!--&lt;!&ndash;              <site rgba="1 0 0 1" size="0.0006" pos="0 0 0" name="center_site"/>&ndash;&gt;-->
<!--        </body>-->

<!--        <body pos="0.0 0.0 0.0" name="working_station">-->
<!--&lt;!&ndash;		    <body pos="0.0 0.0 0.0" name="table0">&ndash;&gt;-->
<!--&lt;!&ndash;			    <geom size="0.5 0.3 0.1" type="box" mass="2000" group="0" name="table_collision" material="table_mat"/>&ndash;&gt;-->
<!--&lt;!&ndash;			    <geom size="0.5 0.3 0.1" type="box" mass="1e-8" group="1" name="table_visual" material="table_mat"/>&ndash;&gt;-->
<!--&lt;!&ndash;                <site name="table0_corner_site1" pos="-0.51 -0.31 -0.06" rgba="1 1 0 1" size="0.005" />&ndash;&gt;-->
<!--&lt;!&ndash;                <site name="table0_corner_site2" pos="-0.51 0.31 -0.06" rgba="0 0 0 0" size="0.005" />&ndash;&gt;-->
<!--&lt;!&ndash;                <site name="table0_corner_site3" pos="0.385 -0.140 -0.023" rgba="0 0 0 0" size="0.005" />&ndash;&gt;-->
<!--&lt;!&ndash;                <site name="table0_corner_site4" pos="0.385 0.140 -0.023" rgba="0 0 0 0" size="0.005" />&ndash;&gt;-->
<!--&lt;!&ndash;                <site name="table0_corner_site5" pos="-0.385 -0.140 0.0233" rgba="0 0 0 0" size="0.005" />&ndash;&gt;-->
<!--&lt;!&ndash;                <site name="table0_corner_site6" pos="-0.385 0.140 0.0233" rgba="0 0 0 0" size="0.005" />&ndash;&gt;-->
<!--&lt;!&ndash;                <site name="table0_corner_site7" pos="0.385 -0.140 0.0233" rgba="0 0 0 0" size="0.005" />&ndash;&gt;-->
<!--&lt;!&ndash;                <site name="table0_corner_site8" pos="0.385 0.140 0.0233" rgba="0 0 0 0" size="0.005" />&ndash;&gt;-->
<!--&lt;!&ndash;                <site name="table0_bottom_site" pos="0.0 0.0 -0.0" rgba="0 0 0 0" size="0.0066" />&ndash;&gt;-->
<!--&lt;!&ndash;                <site name="table0_top_site" pos="0.0 0.0 0.02" rgba="0 0 0 0" size="0.0066" />&ndash;&gt;-->
<!--&lt;!&ndash;                <site name="table0_horizontal_radius_site" pos="0.0 0.0 0.0" rgba="1 1 0 1" size="0.18" />&ndash;&gt;-->
<!--&lt;!&ndash;&lt;!&ndash;                <geom pos="0.5 0.3 0.2" size="0.25 0.15 0.005" type="box" group="0" name="panel_collision" />&ndash;&gt;&ndash;&gt;-->
<!--&lt;!&ndash;&lt;!&ndash;                <geom pos="0.5 0.3 0.2" size="0.25 0.15 0.005" type="box" conaffinity="0" contype="0" group="1" name="panel_visual" material="table_mat_gray"/>&ndash;&gt;&ndash;&gt;-->
<!--&lt;!&ndash;		    </body>&ndash;&gt;-->
<!--            -->
<!--            <body name="insertion_hole_3" pos="-0.2 0.07 0.032" quat="0.7073883 0 0.7068252 0">-->
<!--                <geom pos="0 -0.00665  0" size="0.01 0.0032  0.00875 " type="box" solimp="0.998 0.998 0.001" solref="0.02 1" density="100" friction="0.95 0.3 0.2" group="0" condim="4" material="smetal" />-->
<!--                <geom pos="0.0 0 -0.00665" size="0.01 0.00625 0.0031 " type="box" solimp="0.998 0.998 0.001" solref="0.02 1" density="100" friction="0.95 0.3 0.1" group="0" condim="4" material="smetal" />-->
<!--                <geom pos="0.0 0 0.00665" size="0.01 0.00625 0.0031 " type="box" solimp="0.998 0.998 0.001" solref="0.02 1" density="100" friction="0.95 0.3 0.1" group="0" condim="4" material="smetal" />-->
<!--                <geom pos="0 0.00665 0" size="0.01 0.0032 0.00875 " type="box" solimp="0.998 0.998 0.001" solref="0.02 1" density="100" friction="0.95 0.3 0.1" group="0" condim="4" material="smetal" />-->
<!--                <geom pos="0.01 0 0" size="0.0021 0.00875 0.00875 " type="box" solimp="0.998 0.998 0.001" solref="0.02 1" density="100" friction="0.95 0.3 0.1" group="0" condim="4" material="smetal" />-->
<!--                <site group="0" name="hole-wire,0,90,180,270,conn_site1" pos="0.008 0 0" rgba="0.9019 0.0980 0.2941 0.3" size="0.0035" />-->
<!--                <site name="insertion_hole_3_horizontal_radius_site" pos="0.0 0.0 0.0" rgba="0 0 0 0" size="0.012" />-->
<!--&lt;!&ndash;                    <site rgba="1 0 0 1" size="0.001" pos="0.0108 0 0" name="handle_site"/>&ndash;&gt;-->
<!--&lt;!&ndash;                    <site rgba="1 0 0 1" size="0.0006" pos="0 0 0" name="center_site"/>&ndash;&gt;-->
<!--            </body>-->
<!--        </body>-->

    </worldbody>
<!--    <tendon>-->
<!--&lt;!&ndash;        <spatial limited="true" range="0 0.2" width="0.01" rgba="0.1 0.1 0.1 1">&ndash;&gt;-->
<!--        <spatial limited="true" range="0 0.4" width="0.01" rgba="0.7 0.7 0.7 1" damping="0.5">-->
<!--            <site site="wire1_end"/>-->
<!--            <site site="wire2_end"/>-->
<!--        </spatial>-->
<!--    </tendon>-->

<!--    <include file='assets/actuator0.xml'/>-->
<!--    <include file='assets/actuator1.xml'/>-->

</mujoco>
