<mujoco model="panda">
    <include file="./robot_default.xml"/>

    <actuator>
        <!-- Physical limits of the actuator. -->
        <!-- <motor ctrllimited="true" ctrlrange="-80.0 80.0" joint="joint1" name="torq_right_j0"/>
        <motor ctrllimited="true" ctrlrange="-80.0 80.0" joint="joint2" name="torq_right_j1"/>
        <motor ctrllimited="true" ctrlrange="-80.0 80.0" joint="joint3" name="torq_right_j2"/>
        <motor ctrllimited="true" ctrlrange="-80.0 80.0" joint="joint4" name="torq_right_j3"/>
        <motor ctrllimited="true" ctrlrange="-80.0 80.0" joint="joint5" name="torq_right_j4"/>
        <motor ctrllimited="true" ctrlrange="-12.0 12.0" joint="joint6" name="torq_right_j5"/>
        <motor ctrllimited="true" ctrlrange="-12.0 12.0" joint="joint7" name="torq_right_j6"/> -->
        <velocity ctrllimited="true" ctrlrange="-2.1750 2.1750" joint="joint1" kv="8.0" name="vel_right_j1"/>
        <velocity ctrllimited="true" ctrlrange="-2.1750 2.1750" joint="joint2" kv="7.0" name="vel_right_j2"/>
        <velocity ctrllimited="true" ctrlrange="-2.1750 2.1750" joint="joint3" kv="6.0" name="vel_right_j3"/>
        <velocity ctrllimited="true" ctrlrange="-2.1750 2.1750" joint="joint4" kv="4.0" name="vel_right_j4"/>
        <velocity ctrllimited="true" ctrlrange="-2.6100 2.6100" joint="joint5" kv="2.0" name="vel_right_j5"/>
        <velocity ctrllimited="true" ctrlrange="-2.6100 2.6100" joint="joint6" kv="0.5" name="vel_right_j6"/>
        <velocity ctrllimited="true" ctrlrange="-2.6100 2.6100" joint="joint7" kv="0.1" name="vel_right_j7"/>
    </actuator>

    <!-- <default>
       <joint damping=".1"/>
    </default> -->
    
    <!-- <default>
        <default class="panda">
        <material specular="0.5" shininess="0.25"/>

        <default class="robot_visual">
            <geom type="mesh" contype="0" conaffinity="0" group="1"/>
        </default>
        <default class="robot_collision">
            <geom type="mesh" group="0"/>
            <default class="fingertip_pad_collision_1">
            <geom type="box" size="0.0085 0.004 0.0085" pos="0 0.0055 0.0445"/>
            </default>
            <default class="fingertip_pad_collision_2">
            <geom type="box" size="0.003 0.002 0.003" pos="0.0055 0.002 0.05"/>
            </default>
            <default class="fingertip_pad_collision_3">
            <geom type="box" size="0.003 0.002 0.003" pos="-0.0055 0.002 0.05"/>
            </default>
            <default class="fingertip_pad_collision_4">
            <geom type="box" size="0.003 0.002 0.0035" pos="0.0055 0.002 0.0395"/>
            </default>
            <default class="fingertip_pad_collision_5">
            <geom type="box" size="0.003 0.002 0.0035" pos="-0.0055 0.002 0.0395"/>
            </default>
        </default>
        </default>
    </default> -->

    <asset>
        <material class="panda" name="white" rgba="1 1 1 1"/>
        <material class="panda" name="off_white" rgba="0.901961 0.921569 0.929412 1"/>
        <material class="panda" name="black" rgba="0.25 0.25 0.25 1"/>
        <material class="panda" name="green" rgba="0 1 0 1"/>
        <material class="panda" name="light_blue" rgba="0.039216 0.541176 0.780392 1"/>

        <!-- Collision meshes -->
        <mesh name="link0" file="meshes/link0.stl" />
        <mesh name="link1" file="meshes/link1.stl" />
        <mesh name="link2" file="meshes/link2.stl" />
        <mesh name="link3" file="meshes/link3.stl" />
        <mesh name="link4" file="meshes/link4.stl" />
        <mesh name="link5" file="meshes/link5.stl" />
        <mesh name="link6" file="meshes/link6.stl" />
        <mesh name="link7" file="meshes/link7.stl" />
        <mesh name="link5_c0" file="meshes/link5_collision_0.stl"/>
        <mesh name="link5_c1" file="meshes/link5_collision_1.stl"/>
        <mesh name="link5_c2" file="meshes/link5_collision_2.stl"/>

        <!-- Visual meshes -->
        <!-- <mesh name="link0_vis" file="meshes/link0_vis.stl" />
        <mesh name="link1_vis" file="meshes/link1_vis.stl" />
        <mesh name="link2_vis" file="meshes/link2_vis.stl" />
        <mesh name="link3_vis" file="meshes/link3_vis.stl" />
        <mesh name="link4_vis" file="meshes/link4_vis.stl" />
        <mesh name="link5_vis" file="meshes/link5_vis.stl" />
        <mesh name="link6_vis" file="meshes/link6_vis.stl" />
        <mesh name="link7_vis" file="meshes/link7_vis.stl" />
        <mesh file="meshes/pedestal.stl" name="pedestal"/> -->
        <mesh name="link0_0_vis" file="meshes/link0_0_vis.stl"/>
        <mesh name="link0_1_vis" file="meshes/link0_1_vis.stl"/>
        <mesh name="link0_2_vis" file="meshes/link0_2_vis.stl"/>
        <mesh name="link0_3_vis" file="meshes/link0_3_vis.stl"/>
        <mesh name="link0_4_vis" file="meshes/link0_4_vis.stl"/>
        <mesh name="link0_5_vis" file="meshes/link0_5_vis.stl"/>
        <mesh name="link0_7_vis" file="meshes/link0_7_vis.stl"/>
        <mesh name="link0_8_vis" file="meshes/link0_8_vis.stl"/>
        <mesh name="link0_9_vis" file="meshes/link0_9_vis.stl"/>
        <mesh name="link0_10_vis" file="meshes/link0_10_vis.stl"/>
        <mesh name="link0_11_vis" file="meshes/link0_11_vis.stl"/>
        <mesh name="link1_vis" file="meshes/link1_vis.stl"/>
        <mesh name="link2_vis" file="meshes/link2_vis.stl"/>
        <mesh name="link3_0_vis" file="meshes/link3_0_vis.stl"/>
        <mesh name="link3_1_vis" file="meshes/link3_1_vis.stl"/>
        <mesh name="link3_2_vis" file="meshes/link3_2_vis.stl"/>
        <mesh name="link3_3_vis" file="meshes/link3_3_vis.stl"/>
        <mesh name="link4_0_vis" file="meshes/link4_0_vis.stl"/>
        <mesh name="link4_1_vis" file="meshes/link4_1_vis.stl"/>
        <mesh name="link4_2_vis" file="meshes/link4_2_vis.stl"/>
        <mesh name="link4_3_vis" file="meshes/link4_3_vis.stl"/>
        <mesh name="link5_0_vis" file="meshes/link5_0_vis.stl"/>
        <mesh name="link5_1_vis" file="meshes/link5_1_vis.stl"/>
        <mesh name="link5_2_vis" file="meshes/link5_2_vis.stl"/>
        <mesh name="link6_0_vis" file="meshes/link6_0_vis.stl"/>
        <mesh name="link6_1_vis" file="meshes/link6_1_vis.stl"/>
        <mesh name="link6_2_vis" file="meshes/link6_2_vis.stl"/>
        <mesh name="link6_3_vis" file="meshes/link6_3_vis.stl"/>
        <mesh name="link6_4_vis" file="meshes/link6_4_vis.stl"/>
        <mesh name="link6_5_vis" file="meshes/link6_5_vis.stl"/>
        <mesh name="link6_6_vis" file="meshes/link6_6_vis.stl"/>
        <!-- <mesh file="meshes/link6_7_vis.stl"/> -->
        <mesh name="link6_8_vis" file="meshes/link6_8_vis.stl"/>
        <mesh name="link6_9_vis" file="meshes/link6_9_vis.stl"/>
        <mesh name="link6_10_vis" file="meshes/link6_10_vis.stl"/>
        <mesh name="link6_11_vis" file="meshes/link6_11_vis.stl"/>
        <!-- <mesh file="meshes/link6_12_vis.stl"/> -->
        <mesh name="link6_13_vis" file="meshes/link6_13_vis.stl"/>
        <mesh name="link6_14_vis" file="meshes/link6_14_vis.stl"/>
        <mesh name="link6_15_vis" file="meshes/link6_15_vis.stl"/>
        <mesh name="link6_16_vis" file="meshes/link6_16_vis.stl"/>
        <mesh name="link7_0_vis" file="meshes/link7_0_vis.stl"/>
        <mesh name="link7_1_vis" file="meshes/link7_1_vis.stl"/>
        <mesh name="link7_2_vis" file="meshes/link7_2_vis.stl"/>
        <mesh name="link7_3_vis" file="meshes/link7_3_vis.stl"/>
        <mesh name="link7_4_vis" file="meshes/link7_4_vis.stl"/>
        <mesh name="link7_5_vis" file="meshes/link7_5_vis.stl"/>
        <mesh name="link7_6_vis" file="meshes/link7_6_vis.stl"/>
        <mesh name="link7_7_vis" file="meshes/link7_7_vis.stl"/>
        <!-- <mesh file="hand_0_vis.stl"/>
        <mesh file="hand_1_vis.stl"/>
        <mesh file="hand_2_vis.stl"/>
        <mesh file="hand_3_vis.stl"/>
        <mesh file="hand_4_vis.stl"/>
        <mesh file="finger_0_vis.stl"/>
        <mesh file="finger_1_vis.stl"/> -->
        

<!--        <texture builtin="gradient" height="256" rgb1=".9 .9 1." rgb2=".2 .3 .4" type="skybox" width="256"/>-->
<!--        <texture builtin="checker" height="512" name="texplane" rgb1=".2 .3 .4" rgb2=".1 0.15 0.2" type="2d" width="512"/>-->
<!--        <material name="floorplane" reflectance="0.5" texrepeat="1 1" texture="texplane" texuniform="true"/>-->
    </asset>
    <worldbody>
<!--        <geom condim="3" material="floorplane" name="FLOOR" pos="0 0 -0.89" size="3 3 .125" type="plane"/>-->
        <body name="link0" pos="0 0 0">
            <body name="base" pos="0 0 0">
                <inertial diaginertia="0 0 0" mass="0" pos="0 0 0"/>
                <!-- <body name="controller_box" pos="0 0 0">
                    <inertial diaginertia="1.71363 1.27988 0.809981" mass="46.64" pos="-0.325 0 -0.38"/>
                    <geom pos="-0.325 0 -0.38" size="0.11 0.2 0.265" type="box" name="controller_box_col"/>
                </body> -->
                <!-- <body name="pedestal_feet" pos="0 0 0">
                    <inertial diaginertia="8.16095 9.59375 15.0785" mass="167.09" pos="-0.1225 0 -0.758"/>
                    <geom pos="-0.1225 0 -0.758" size="0.385 0.35 0.155" type="box" name="pedestal_feet_col"/>
                </body> -->
                <body name="torso" pos="0 0 0">
                    <inertial diaginertia="1e-08 1e-08 1e-08" mass="0.0001" pos="0 0 0"/>
                    <geom conaffinity="0" contype="0" group="1" rgba="0.2 0.2 0.2 1" size="0.05 0.05 0.05" type="box" name="torso_col"/>
                </body>
                <body name="pedestal" pos="0 0 0">
                    <inertial diaginertia="6.0869 5.81635 4.20915" mass="60.864" pos="0 0 0" quat="0.659267 -0.259505 -0.260945 0.655692"/>
                    <!-- <geom conaffinity="0" contype="0" group="1" mesh="pedestal" pos="0.26 0.345 -0.91488" quat="0.5 0.5 -0.5 -0.5" rgba="0.2 0.2 0.2 1" type="mesh" name="pedestal_col1"/> -->
                    <!-- <geom pos="-0.02 0 -0.29" rgba="0.2 0.2 0.2 1" size="0.18 0.31" type="cylinder" name="pedestal_col2"/> -->
                    <geom pos="0 0 -0.445" rgba=".7 .5 .3 1" size="0.4 0.4 0.465" type="box" name="base_box"/>
                    <geom pos="0 0 -0.445" rgba=".7 .5 .3 1" size="0.4 0.4 0.465" type="box" name="base_box_visual" conaffinity="0" contype="0" group="1"/>
                    <site pos="0.25 0.33 -0.89" name="pedestal_bottom" rgba="1 1 0 1" size="0.0055"/>
                </body>
            </body>
            <inertial pos="0 0 0.05" mass="4" diaginertia="0.4 0.4 0.4" />
            <!-- <geom type="mesh" contype="0" conaffinity="0" group="1" mesh="link0_vis" name="link0_visual" rgba="1 1 1 1"/> -->
            <geom mesh="link0_0_vis" material="off_white" name="link0_0_visual" class="robot_visual"/>
            <geom mesh="link0_1_vis" material="black" name="link0_1_visual" class="robot_visual"/>
            <geom mesh="link0_2_vis" material="off_white" name="link0_2_visual" class="robot_visual"/>
            <geom mesh="link0_3_vis" material="black" name="link0_3_visual" class="robot_visual"/>
            <geom mesh="link0_4_vis" material="off_white" name="link0_4_visual" class="robot_visual"/>
            <geom mesh="link0_5_vis" material="black" name="link0_5_visual" class="robot_visual"/>
            <geom mesh="link0_7_vis" material="white" name="link0_7_visual" class="robot_visual"/>
            <geom mesh="link0_8_vis" material="white" name="link0_8_visual" class="robot_visual"/>
            <geom mesh="link0_9_vis" material="black" name="link0_9_visual" class="robot_visual"/>
            <geom mesh="link0_10_vis" material="off_white" name="link0_10_visual" class="robot_visual"/>
            <geom mesh="link0_11_vis" material="white" name="link0_11_visual" class="robot_visual"/>
            <geom type="mesh" group="0" mesh="link0" name="link0_collision"/>
            <!-- <site name="link0" size=".05" rgba="0.9019 0.0980 0.2941 0.3" type="sphere"/> -->
            <body name="link1" pos="0 0 0.333">
                <inertial pos="0 0 -0.07" mass="3" diaginertia="0.3 0.3 0.3" />
                <joint name="joint1" damping=".1" pos="0 0 0" axis="0 0 1" limited="true" range="-2.8973 2.8973" />
                <!-- <geom type="mesh" contype="0" conaffinity="0" group="1" mesh="link1_vis" name="link1_visual" rgba="1 1 1 1"/> -->
                <geom material="white" mesh="link1_vis" name="link1_visual" class="robot_visual"/>
                <geom type="mesh" group="0" mesh="link1" name="link1_collision"/>
                <body name="link2" pos="0 0 0" quat="0.707107 -0.707107 0 0">
                    <inertial pos="0 -0.1 0" mass="3" diaginertia="0.3 0.3 0.3" />
                    <joint name="joint2" damping=".1" pos="0 0 0" axis="0 0 1" limited="true" range="-1.7628 1.7628" />
                    <!-- <geom type="mesh" contype="0" conaffinity="0" group="1" mesh="link2_vis" name="link2_visual" rgba="1 1 1 1"/> -->
                    <geom material="white" mesh="link2_vis" name="link2_visual" class="robot_visual"/>
                    <geom type="mesh" group="0" mesh="link2" name="link2_collision"/>
                    <body name="link3" pos="0 -0.316 0" quat="0.707107 0.707107 0 0">
                        <inertial pos="0.04 0 -0.05" mass="2" diaginertia="0.2 0.2 0.2" />
                        <joint name="joint3" damping=".1" pos="0 0 0" axis="0 0 1" limited="true" range="-2.8973 2.8973" />
                        <!-- <geom type="mesh" contype="0" conaffinity="0" group="1" mesh="link3_vis" name="link3_visual" rgba="1 1 1 1"/> -->
                        <geom mesh="link3_0_vis" material="white" name="link3_0_visual" class="robot_visual"/>
                        <geom mesh="link3_1_vis" material="white" name="link3_1_visual" class="robot_visual"/>
                        <geom mesh="link3_2_vis" material="white" name="link3_2_visual" class="robot_visual"/>
                        <geom mesh="link3_3_vis" material="black" name="link3_3_visual" class="robot_visual"/>
                        <geom type="mesh" group="0" mesh="link3" name="link3_collision"/>
                        <body name="link4" pos="0.0825 0 0" quat="0.707107 0.707107 0 0">
                            <inertial pos="-0.04 0.05 0" mass="2" diaginertia="0.2 0.2 0.2" />
                            <joint name="joint4" damping=".1" pos="0 0 0" axis="0 0 1" limited="true" range="-3.0718 -0.0698" />
                            <!-- <geom type="mesh" contype="0" conaffinity="0" group="1" mesh="link4_vis" name="link4_visual" rgba="1 1 1 1"/> -->
                            <geom mesh="link4_0_vis" material="white" name="link4_0_visual" class="robot_visual"/>
                            <geom mesh="link4_1_vis" material="white" name="link4_1_visual" class="robot_visual"/>
                            <geom mesh="link4_2_vis" material="black" name="link4_2_visual" class="robot_visual"/>
                            <geom mesh="link4_3_vis" material="white" name="link4_3_visual" class="robot_visual"/>
                            <geom type="mesh" group="0" mesh="link4" name="link4_collision"/>
                            <body name="link5" pos="-0.0825 0.384 0" quat="0.707107 -0.707107 0 0">
                                <inertial pos="0 0 -0.15" mass="2" diaginertia="0.2 0.2 0.2" />
                                <joint name="joint5" damping=".1" pos="0 0 0" axis="0 0 1" limited="true" range="-2.8973 2.8973" />
                                <!-- <geom type="mesh" contype="0" conaffinity="0" group="1" mesh="link5_vis" name="link5_visual" rgba="1 1 1 1"/> -->
                                <geom mesh="link5_0_vis" material="black" name="link5_0_visual" class="robot_visual"/>
                                <geom mesh="link5_1_vis" material="white" name="link5_1_visual" class="robot_visual"/>
                                <geom mesh="link5_2_vis" material="white" name="link5_2_visual" class="robot_visual"/>
                                <!-- <geom mesh="link5_c0_collision" name="link5_0_collision" class="robot_collision"/>
                                <geom mesh="link5_c1_collision" name="link5_1_collision" class="robot_collision"/>
                                <geom mesh="link5_c2_collision" name="link5_2_collision" class="robot_collision"/> -->
                                <geom type="mesh" group="0" mesh="link5" name="link5_collision"/>
                                <body name="link6" pos="0 0 0" quat="0.707107 0.707107 0 0">
                                    <inertial pos="0.06 0 0" mass="1.5" diaginertia="0.1 0.1 0.1" />
                                    <joint name="joint6" damping=".1" pos="0 0 0" axis="0 0 1" limited="true" range="-0.0175 3.7525" />
                                    <!-- <geom type="mesh" contype="0" conaffinity="0" group="1" mesh="link6_vis" name="link6_visual" rgba="1 1 1 1"/> -->
                                    <geom mesh="link6_0_vis" material="off_white" name="link6_0_visual" class="robot_visual"/>
                                    <geom mesh="link6_1_vis" material="white" name="link6_1_visual" class="robot_visual"/>
                                    <geom mesh="link6_2_vis" material="black" name="link6_2_visual" class="robot_visual"/>
                                    <geom mesh="link6_3_vis" material="white" name="link6_3_visual" class="robot_visual"/>
                                    <geom mesh="link6_4_vis" material="white" name="link6_4_visual" class="robot_visual"/>
                                    <geom mesh="link6_5_vis" material="white" name="link6_5_visual" class="robot_visual"/>
                                    <geom mesh="link6_6_vis" material="white" name="link6_6_visual" class="robot_visual"/>
                                    <!-- <geom mesh="link6_7_vis" material="light_blue"  name="link6_7_visual" class="robot_visual"/> -->
                                    <geom mesh="link6_8_vis" material="light_blue" name="link6_8_visual" class="robot_visual"/>
                                    <geom mesh="link6_9_vis" material="black" name="link6_9_visual" class="robot_visual"/>
                                    <geom mesh="link6_10_vis" material="black" name="link6_10_visual" class="robot_visual"/>
                                    <geom mesh="link6_11_vis" material="white" name="link6_11_visual" class="robot_visual"/>
                                    <!-- <geom mesh="link6_12_vis" material="green" name="link6_12_visual" class="robot_visual"/> -->
                                    <geom mesh="link6_13_vis" material="white" name="link6_13_visual" class="robot_visual"/>
                                    <geom mesh="link6_14_vis" material="black" name="link6_14_visual" class="robot_visual"/>
                                    <geom mesh="link6_15_vis" material="black" name="link6_15_visual" class="robot_visual"/>
                                    <geom mesh="link6_16_vis" material="white" name="link6_16_visual" class="robot_visual"/>
                                    <geom type="mesh" group="0" mesh="link6" name="link6_collision"/>
                                    <body name="link7" pos="0.088 0 0" quat="0.707107 0.707107 0 0">
                                        <inertial pos="0 0 0.08" mass="0.5" diaginertia="0.05 0.05 0.05" />
                                        <joint name="joint7" damping=".1" pos="0 0 0" axis="0 0 1" limited="true" range="-2.8973 2.8973" />
                                        <!-- <geom type="mesh" contype="0" conaffinity="0" group="1" mesh="link7_vis" name="link7_visual" rgba="1 1 1 1"/> -->
                                        <geom mesh="link7_0_vis" material="white" name="link7_0_visual" class="robot_visual"/>
                                        <geom mesh="link7_1_vis" material="black" name="link7_1_visual" class="robot_visual"/>
                                        <geom mesh="link7_2_vis" material="black" name="link7_2_visual" class="robot_visual"/>
                                        <geom mesh="link7_3_vis" material="black" name="link7_3_visual" class="robot_visual"/>
                                        <geom mesh="link7_4_vis" material="black" name="link7_4_visual" class="robot_visual"/>
                                        <geom mesh="link7_5_vis" material="black" name="link7_5_visual" class="robot_visual"/>
                                        <geom mesh="link7_6_vis" material="black" name="link7_6_visual" class="robot_visual"/>
                                        <geom mesh="link7_7_vis" material="white" name="link7_7_visual" class="robot_visual"/>
                                        <geom type="mesh" group="0" mesh="link7" name="link7_collision"/>
                                        <!-- to add gripper -->
                                        <!-- rotate 45deg to align physically to the tool-->
                                        <body name="right_hand" pos="0 0 0.107" quat="0.924 0 0 0.383">
                                            <inertial pos="0 0 0" mass="0.5" diaginertia="0.05 0.05 0.05" />
                                            <!-- This sites were removed from visualization. -->
                                            <site name="ee" pos="0 0 0" size="0.01 0.01 0.01" rgba="0 0 0 0" type="sphere" group="1"/> <!-- 0 0 1 1 -->
                                            <site name="ee_x" pos="0 0 0" size="0.005 .1"  quat="0.707105 0.707108 0 0 " rgba="0 0 0 0" type="cylinder" group="1"/> <!-- 1 0 0 1 -->
                                            <site name="ee_z" pos="0 0 0" size="0.005 .1" quat="0.707105 0 0 0.707108" rgba="0 0 0 0" type="cylinder" group="1"/> <!-- 0 0 1 1 -->
                                            <site name="ee_y" pos="0 0 0" size="0.005 .1" quat="0.707105 0 0.707108 0 " rgba="0 0 0 0" type="cylinder" group="1"/> <!-- 0 1 0 1 -->
                                        </body>
                                    </body>
                                </body>
                            </body>
                        </body>
                    </body>
                </body>
            </body>
        </body>
        <light pos="0 0 1.5" dir="0 0 -1" directional="false"/>
    </worldbody>
</mujoco>
